Workbook
Name AbrEspaciamiento: #REF!
Name Ape_osi: Leyenda!$G$47:$H$51
Name Apertura: Leyenda!$B$47:$D$51
Name Met_osi: Leyenda!$F$39:$G$43
Name Meteorizacion: Leyenda!$B$39:$D$43
Name Per_osi: Leyenda!$F$30:$G$34
Name Persistencia: Leyenda!$B$30:$D$34
Name Rell_osi: Leyenda!$F$63:$G$67
Name Relleno: Leyenda!$B$63:$D$67
Name Resistencia: Leyenda!$B$4:$B$10
Name RQD: Leyenda!$D$13:$D$17
Name Rug_osi: Leyenda!$F$55:$G$59
Name Rugosidad: Leyenda!$B$54:$D$59

Sheet 1. Collar_survey_assay
A1: Local | B1: FURO | C1: Sonda | D1: Inclinación | E1: Profundidade (m) | F1: Dip Direction (°) | G1: Dip(°) | H1: Sondagem | I1: Norte (m) | J1: Leste (m) | K1: Nivel (m)
A2: BREJO SECO | B2: GEOTEC-01 | C2: GEOMINAS | D2: Vertical | E2: 60 | F2: 0 | G2: 90 | H2: Mista | I2: 9063816.7 | J2: 173695.42 | K2: 481.37
A3: BREJO SECO | B3: GEOTEC-02 | C3: GEOMINAS | D3: Inclinado | E3: 60 | F3: 270 | G3: 60 | H3: Mista | I3: 9063476.4 | J3: 174445.89 | K3: 506.972
A4: BREJO SECO | B4: GEOTEC-03 | C4: GEOMINAS | D4: Inclinado | E4: 60 | F4: 210 | G4: 60 | H4: Mista | I4: 9063223.8 | J4: 174709.9 | K4: 495.89
A5: BREJO SECO | B5: GEOTEC-04 | C5: GEOMINAS | D5: Inclinado | E5: 40 | F5: 150 | G5: 60 | H5: Mista | I5: 9063631 | J5: 174188.99 | K5: 499.143
A6: BREJO SECO | B6: PZ-BS-03 | C6: GEOMINAS | D6: Vertical | E6: 30 | F6: 0 | G6: 90 | H6: Mista | I6: 9063713.8 | J6: 173859.73 | K6: 491.768
A7: BREJO SECO | B7: PZ-BS-01 | C7: GEOMINAS | D7: Vertical | E7: 30 | F7: 0 | G7: 90 | H7: Mista | I7: 9063323.5 | J7: 174430.18 | K7: 506.68
A8: BREJO SECO | B8: PPN-BS-DD01 | C8: GEOSOL | D8: Vertical | E8: 80 | F8: 0 | G8: 90 | H8: Mista | I8: 9063705.7 | J8: 173847.33 | K8: 491.89
A9: BREJO SECO | B9: PPN-BS-DD02 | C9: GEOSOL | D9: Vertical | E9: 80 | F9: 0 | G9: 90 | H9: Mista | I9: 9063617.3 | J9: 174185.92 | K9: 500.07
A10: BREJO SECO | B10: PPN-BS-DD03 | C10: GEOSOL | D10: Vertical | E10: 80 | F10: 0 | G10: 90 | H10: Mista | I10: 9063205.2 | J10: 174676.02 | K10: 497.19
A11: BREJO SECO | B11: PPN-BS-DD04 | C11: GEOSOL | D11: Vertical | E11: 40 | F11: 0 | G11: 90 | H11: Mista | I11: 9063849 | J11: 174695.82 | K11: 408.64
A12: BREJO SECO | B12: PPN-BS-DD05 | C12: GEOSOL | D12: Vertical | E12: 40 | F12: 0 | G12: 90 | H12: Mista | I12: 9064232.5 | J12: 174392.73 | K12: 391.9
A13: BREJO SECO | B13: PPN-BS-DD06 | C13: GEOSOL | D13: Vertical | E13: 40 | F13: 0 | G13: 90 | H13: Mista | I13: 9064178.8 | J13: 174342.87 | K13: 395.06
... A22: BREJO SECO | B22: PPN-BS-DD15 | C22: GEOSOL | D22: Vertical | E22: 40 | F22: 0 | G22: 90 | H22: Mista | I22: 9063497.9 | J22: 172350.38 | K22: 431
E23: =+SUM(E2:E22) -> 1000
E24: =1000-40*7 -> 720

Sheet 2. Logging Brejo Seco
U1: =2.2/2.6*100 -> 84.615385 | AE1: Piaui nickel metais | AF1: Caracterizacao Geotecnica
A2: MINE | B2: YEAR | C2: Realizado | D2: DDHH | E2: Cod Modelo Snowden | F2: Cod photo | G2: Litology (Snowden) Block Model | H2: Lithology (Quimica SGS) | I2: Lito Code Quimica & Comentario | J2: Comnetaios Logueo | K2: From (m) | L2: To (m) | M2: Lenght (m) | N2: Recuperation Furo Rock /Soil(%) | O2: %Soil in Drillhole | P2: Longitud Recuperada (m) | Q2: Longitud Recuperada | R2: Espaciamiento (mm) | S2: Frecuencia Fraturas | T2: Longitud recuperada (m) | U2: RQD_Piaui nickel (m) | V2: RQD (%) | W2: Numero Fracturas Visibles | X2: Numero Fracturas No Visibles | Y2: Fracturas Totales | Z2: Espaciamiento (mm) | AA2: RQD (%) Geominas | AB2: Grau de Alteracao | AC2: Grau de Fraturamento | AD2: Grau de ocorrencia | AE2: Numero Fraturas x metro | AF2: Espacamiento (mm) | AG2: Resistencia GEOMINAS vs Piauí | AH2: Material Classification | AI2: Blasting Index Mohamed | AJ2: Blastability Index | AK2: Blasting | AL2: Resistencia Piaui (Campo) | AM2: Resistencia Piauí Niquel | AN2: Persistencia\ | AO2: Meteorizacion | AP2: Apertura | AQ2: Rugosidade | AR2: Relleno | AS2: Agua | AT2: Comentarios | AV2: Persistencia\ | AW2: Meteorizacion | AX2: Apertura | AY2: Rugosidade | AZ2: Preenchimento | BA2: Suma de Condiciones Juntas | BB2: Ratio89 RQD | BC2: Ratio89_Resistencia | BD2: Ratio89_Espaciamiento | BE2: Ratio89_Discontinuidades | BF2: RatioAgua | BG2: GSI (RQD menor 80) | BH2: Ratio 76 Resistencia | BI2: Ratio76 Espaciamiento | BJ2: Ratio76 RQD | BK2: Ratio76 Apertura | BL2: Ratio76 Rugosidade | BM2: Ratio76 Preenchimento | BN2: Ratio76 Meteorizacion | BO2: Ratio76 Persistencia | BP2: RatioAgua | BQ2: RMR76 | BR2: RMR89 | BS2: Recuperacion de Sulos | BT2: Observaciones de descontinuidades
A3: Brejo Seco | B3: 2024 | C3: PNM | D3: GEOTEC-01 | E3: 60 | F3: 60 | G3: P025_Cob | H3: =+F3 -> 60 | J3: Saprolito, areno argiloso | K3: 0 | L3: 0.5 | M3: =+L3-K3 -> 0.5 | N3: 0.98 | O3: =1-N3 -> 0.02 | P3: =+M3*N3 -> 0.49 | Q3: =+N3*M3 -> 0.49 | R3: 490 | S3: 1 | T3: =+N3*M3 -> 0.49 | U3: 0 | V3: 0 | Z3: 0 | AA3: 58 | AB3: A5 | AC3: F5 | AD3: C4 | AE3: 20 | AF3: 24.5 | AG3: S2 | AH3: R0 | AI3: =+VLOOKUP(AH3,Leyenda!$O$4:$U$10,6,FALSE) -> 0 | AJ3: =+VLOOKUP(AH3,Leyenda!$O$4:$U$10,7,FALSE) -> No Blasting need | AK3: =+VLOOKUP(AJ3,Leyenda!$U$4:$V$10,2,FALSE) -> 2 | AL3: S2 | AM3: =+AH3 -> R0 | AN3: P5 | AO3: W4 | AP3: A4 | AQ3: G5 | AR3: F4 | AS3: Seco | AT3: Solo consolidaddo | AV3: =+VLOOKUP(AN3,Leyenda!$B$30:$E$34,3,FALSE) -> 0 | AW3: =+VLOOKUP('2. Logging Brejo Seco'!AO3,Meteorizacion,3,FALSE) -> 0 | AX3: =+VLOOKUP('2. Logging Brejo Seco'!AP3,Apertura,3,FALSE) -> 0 | AY3: =+VLOOKUP('2. Logging Brejo Seco'!AQ3,Leyenda!$B$55:$D$59,3,FALSE) -> 0 | AZ3: =+VLOOKUP('2. Logging Brejo Seco'!AR3,Relleno,3,FALSE) -> 0 | BA3: =+SUM(AV3:AZ3) -> 0 | BB3: =ROUND(-0.0002*POWER(V3,2)+0.2197*V3,0) -> 0 | BC3: =VLOOKUP(AM3,Leyenda!$B$4:$D$10,3,FALSE) -> 0 | BD3: =IF(Z3="",ROUND((IF(Z3<=400,1.5478*POWER(Z3,0.3351),-2*POWER(10,-6)*POWER(Z3,2)+0.0091*Z3+8.1704)),0),ROUND((IF(Z3<=400,1.5478*POWER(Z3,0.3351),-2*POWER(10,-6)*POWER(Z3,2)+0.0091*Z3+8.1704)),0)) -> 0 | BE3: =+BA3 -> 0 | BF3: =VLOOKUP(AS3,Leyenda!$B$70:$D$75,3,FALSE) -> 15 | BG3: =1.5*BA3+(V3*0.5) -> 0 | BH3: =VLOOKUP(AM3,Leyenda!$B$4:$E$10,4,FALSE) -> 0 | BI3: =IF(Z3="",ROUND(IF(Z3<=50,5,IF(Z3>=3000,30,6.038*LN(Z3)-19.63)),0),ROUND(IF(Z3<=50,5,IF(Z3>=3000,30,6.038*LN(Z3)-19.63)),0)) -> 5 | BJ3: =ROUND(-0.0002*POWER(V3,2)+0.2197*V3,0) -> 0 | BK3: =+VLOOKUP('2. Logging Brejo Seco'!AP3,Leyenda!$B$47:$E$51,4,FALSE) -> 0 | BL3: =+VLOOKUP('2. Logging Brejo Seco'!AQ3,Leyenda!$B$55:$E$59,4,FALSE) -> 0 | BM3: =+VLOOKUP('2. Logging Brejo Seco'!AR3,Leyenda!$B$63:$E$67,3,FALSE) -> 0 | BN3: =+VLOOKUP('2. Logging Brejo Seco'!AO3,Leyenda!$B$39:$E$43,4,FALSE) -> 0 | BO3: =+VLOOKUP('2. Logging Brejo Seco'!AN3,Leyenda!$B$30:$E$34,4,FALSE) -> 0 | BP3: =VLOOKUP(AS3,Leyenda!$B$71:$E$75,4,FALSE) -> 10 | BQ3: =+BH3+BI3+BJ3+BK3+BL3+BM3+BN3+BO3+BP3 -> 15 | BR3: =+BC3+BD3+BB3+BE3+BF3 -> 15 | BS3: =1-N3 -> 0.02 | BT3: Clasificaçao SUCS (Mecanica de Solos)
A4: Brejo Seco | B4: 2024 | C4: PNM | D4: GEOTEC-01 | E4: 60 | F4: 60 | G4: P025_Cob | H4: =+F4 -> 60 | J4: rocha alterada, canga lateritica | K4: =+L3 -> 0.5 | L4: =+K4+0.5 -> 1 | M4: =+L4-K4 -> 0.5 | N4: 0.98 | O4: =1-N4 -> 0.02 | P4: =+M4*N4 -> 0.49 | Q4: =+N4*M4 -> 0.49 | R4: 490 | S4: 1 | T4: =+N4*M4 -> 0.49 | U4: 0 | V4: 0 | Z4: 0 | AA4: 24 | AB4: A5 | AC4: F5 | AD4: C4 | AE4: 20 | AF4: 24.5 | AG4: S2 | AH4: R0 | AI4: =+VLOOKUP(AH4,Leyenda!$O$4:$U$10,6,FALSE) -> 0 | AJ4: =+VLOOKUP(AH4,Leyenda!$O$4:$U$10,7,FALSE) -> No Blasting need | AK4: =+VLOOKUP(AJ4,Leyenda!$U$4:$V$10,2,FALSE) -> 2 | AL4: S2 | AM4: =+AH4 -> R0 | AN4: P5 | AO4: W4 | AP4: A4 | AQ4: G5 | AR4: F4 | AS4: Seco | AV4: =+VLOOKUP(AN4,Leyenda!$B$30:$E$34,3,FALSE) -> 0 | AW4: =+VLOOKUP('2. Logging Brejo Seco'!AO4,Meteorizacion,3,FALSE) -> 0 | AX4: =+VLOOKUP('2. Logging Brejo Seco'!AP4,Apertura,3,FALSE) -> 0 | AY4: =+VLOOKUP('2. Logging Brejo Seco'!AQ4,Leyenda!$B$55:$D$59,3,FALSE) -> 0 | AZ4: =+VLOOKUP('2. Logging Brejo Seco'!AR4,Relleno,3,FALSE) -> 0 | BA4: =+SUM(AV4:AZ4) -> 0 | BB4: =ROUND(-0.0002*POWER(V4,2)+0.2197*V4,0) -> 0 | BC4: =VLOOKUP(AM4,Leyenda!$B$4:$D$10,3,FALSE) -> 0 | BD4: =IF(Z4="",ROUND((IF(Z4<=400,1.5478*POWER(Z4,0.3351),-2*POWER(10,-6)*POWER(Z4,2)+0.0091*Z4+8.1704)),0),ROUND((IF(Z4<=400,1.5478*POWER(Z4,0.3351),-2*POWER(10,-6)*POWER(Z4,2)+0.0091*Z4+8.1704)),0)) -> 0 | BE4: =+BA4 -> 0 | BF4: =VLOOKUP(AS4,Leyenda!$B$70:$D$75,3,FALSE) -> 15 | BG4: =1.5*BA4+(V4*0.5) -> 0 | BH4: =VLOOKUP(AM4,Leyenda!$B$4:$E$10,4,FALSE) -> 0 | BI4: =IF(Z4="",ROUND(IF(Z4<=50,5,IF(Z4>=3000,30,6.038*LN(Z4)-19.63)),0),ROUND(IF(Z4<=50,5,IF(Z4>=3000,30,6.038*LN(Z4)-19.63)),0)) -> 5 | BJ4: =ROUND(-0.0002*POWER(V4,2)+0.2197*V4,0) -> 0 | BK4: =+VLOOKUP('2. Logging Brejo Seco'!AP4,Leyenda!$B$47:$E$51,4,FALSE) -> 0 | BL4: =+VLOOKUP('2. Logging Brejo Seco'!AQ4,Leyenda!$B$55:$E$59,4,FALSE) -> 0 | BM4: =+VLOOKUP('2. Logging Brejo Seco'!AR4,Leyenda!$B$63:$E$67,3,FALSE) -> 0 | BN4: =+VLOOKUP('2. Logging Brejo Seco'!AO4,Leyenda!$B$39:$E$43,4,FALSE) -> 0 | BO4: =+VLOOKUP('2. Logging Brejo Seco'!AN4,Leyenda!$B$30:$E$34,4,FALSE) -> 0 | BP4: =VLOOKUP(AS4,Leyenda!$B$71:$E$75,4,FALSE) -> 10 | BQ4: =+BH4+BI4+BJ4+BK4+BL4+BM4+BN4+BO4+BP4 -> 15 | BR4: =+BC4+BD4+BB4+BE4+BF4 -> 15 | BS4: =1-N4 -> 0.02 | BT4: Clasificaçao SUCS (Mecanica de Solos)
A5: Brejo Seco | B5: 2024 | C5: PNM | D5: GEOTEC-01 | E5: 60 | F5: 60 | G5: P025_Cob | H5: =+F5 -> 60 | J5: rocha alterada, canga lateritica | K5: =+L4 -> 1 | L5: =+K5+0.5 -> 1.5 | M5: =+L5-K5 -> 0.5 | N5: 0.86 | O5: =1-N5 -> 0.14 | P5: =+M5*N5 -> 0.43 | Q5: =+N5*M5 -> 0.43 | R5: 430 | S5: 1 | T5: =+N5*M5 -> 0.43 | U5: 0 | V5: 0 | Z5: 0 | AA5: 42 | AB5: A4 | AC5: F5 | AD5: C4 | AE5: 20 | AF5: 21.5 | AG5: S2 | AH5: R0 | AI5: =+VLOOKUP(AH5,Leyenda!$O$4:$U$10,6,FALSE) -> 0 | AJ5: =+VLOOKUP(AH5,Leyenda!$O$4:$U$10,7,FALSE) -> No Blasting need | AK5: =+VLOOKUP(AJ5,Leyenda!$U$4:$V$10,2,FALSE) -> 2 | AL5: S2 | AM5: =+AH5 -> R0 | AN5: P5 | AO5: W4 | AP5: A4 | AQ5: G5 | AR5: F4 | AS5: Seco | AV5: =+VLOOKUP(AN5,Leyenda!$B$30:$E$34,3,FALSE) -> 0 | AW5: =+VLOOKUP('2. Logging Brejo Seco'!AO5,Meteorizacion,3,FALSE) -> 0 | AX5: =+VLOOKUP('2. Logging Brejo Seco'!AP5,Apertura,3,FALSE) -> 0 | AY5: =+VLOOKUP('2. Logging Brejo Seco'!AQ5,Leyenda!$B$55:$D$59,3,FALSE) -> 0 | AZ5: =+VLOOKUP('2. Logging Brejo Seco'!AR5,Relleno,3,FALSE) -> 0 | BA5: =+SUM(AV5:AZ5) -> 0 | BB5: =ROUND(-0.0002*POWER(V5,2)+0.2197*V5,0) -> 0 | BC5: =VLOOKUP(AM5,Leyenda!$B$4:$D$10,3,FALSE) -> 0 | BD5: =IF(Z5="",ROUND((IF(Z5<=400,1.5478*POWER(Z5,0.3351),-2*POWER(10,-6)*POWER(Z5,2)+0.0091*Z5+8.1704)),0),ROUND((IF(Z5<=400,1.5478*POWER(Z5,0.3351),-2*POWER(10,-6)*POWER(Z5,2)+0.0091*Z5+8.1704)),0)) -> 0 | BE5: =+BA5 -> 0 | BF5: =VLOOKUP(AS5,Leyenda!$B$70:$D$75,3,FALSE) -> 15 | BG5: =1.5*BA5+(V5*0.5) -> 0 | BH5: =VLOOKUP(AM5,Leyenda!$B$4:$E$10,4,FALSE) -> 0 | BI5: =IF(Z5="",ROUND(IF(Z5<=50,5,IF(Z5>=3000,30,6.038*LN(Z5)-19.63)),0),ROUND(IF(Z5<=50,5,IF(Z5>=3000,30,6.038*LN(Z5)-19.63)),0)) -> 5 | BJ5: =ROUND(-0.0002*POWER(V5,2)+0.2197*V5,0) -> 0 | BK5: =+VLOOKUP('2. Logging Brejo Seco'!AP5,Leyenda!$B$47:$E$51,4,FALSE) -> 0 | BL5: =+VLOOKUP('2. Logging Brejo Seco'!AQ5,Leyenda!$B$55:$E$59,4,FALSE) -> 0 | BM5: =+VLOOKUP('2. Logging Brejo Seco'!AR5,Leyenda!$B$63:$E$67,3,FALSE) -> 0 | BN5: =+VLOOKUP('2. Logging Brejo Seco'!AO5,Leyenda!$B$39:$E$43,4,FALSE) -> 0 | BO5: =+VLOOKUP('2. Logging Brejo Seco'!AN5,Leyenda!$B$30:$E$34,4,FALSE) -> 0 | BP5: =VLOOKUP(AS5,Leyenda!$B$71:$E$75,4,FALSE) -> 10 | BQ5: =+BH5+BI5+BJ5+BK5+BL5+BM5+BN5+BO5+BP5 -> 15 | BR5: =+BC5+BD5+BB5+BE5+BF5 -> 15 | BS5: =1-N5 -> 0.14 | BT5: Clasificaçao SUCS (Mecanica de Solos)
A6: Brejo Seco | B6: 2024 | C6: PNM | D6: GEOTEC-01 | E6: 60 | F6: 60 | G6: P025_Cob | H6: =+F6 -> 60 | J6: rocha alterada, canga lateritica | K6: =+L5 -> 1.5 | L6: =+K6+0.5 -> 2 | M6: =+L6-K6 -> 0.5 | N6: 0.6 | O6: =1-N6 -> 0.4 | P6: =+M6*N6 -> 0.3 | Q6: =+N6*M6 -> 0.3 | R6: 15 | S6: 20 | T6: =+N6*M6 -> 0.3 | U6: 0 | V6: 0 | Z6: 0 | AA6: 58 | AB6: A1 | AC6: F5 | AD6: C4 | AE6: 20 | AF6: 15 | AG6: S2 | AH6: R0 | AI6: =+VLOOKUP(AH6,Leyenda!$O$4:$U$10,6,FALSE) -> 0 | AJ6: =+VLOOKUP(AH6,Leyenda!$O$4:$U$10,7,FALSE) -> No Blasting need | AK6: =+VLOOKUP(AJ6,Leyenda!$U$4:$V$10,2,FALSE) -> 2 | AL6: S2 | AM6: =+AH6 -> R0 | AN6: P5 | AO6: W4 | AP6: A4 | AQ6: G5 | AR6: F4 | AS6: Seco | AV6: =+VLOOKUP(AN6,Leyenda!$B$30:$E$34,3,FALSE) -> 0 | AW6: =+VLOOKUP('2. Logging Brejo Seco'!AO6,Meteorizacion,3,FALSE) -> 0 | AX6: =+VLOOKUP('2. Logging Brejo Seco'!AP6,Apertura,3,FALSE) -> 0 | AY6: =+VLOOKUP('2. Logging Brejo Seco'!AQ6,Leyenda!$B$55:$D$59,3,FALSE) -> 0 | AZ6: =+VLOOKUP('2. Logging Brejo Seco'!AR6,Relleno,3,FALSE) -> 0 | BA6: =+SUM(AV6:AZ6) -> 0 | BB6: =ROUND(-0.0002*POWER(V6,2)+0.2197*V6,0) -> 0 | BC6: =VLOOKUP(AM6,Leyenda!$B$4:$D$10,3,FALSE) -> 0 | BD6: =IF(Z6="",ROUND((IF(Z6<=400,1.5478*POWER(Z6,0.3351),-2*POWER(10,-6)*POWER(Z6,2)+0.0091*Z6+8.1704)),0),ROUND((IF(Z6<=400,1.5478*POWER(Z6,0.3351),-2*POWER(10,-6)*POWER(Z6,2)+0.0091*Z6+8.1704)),0)) -> 0 | BE6: =+BA6 -> 0 | BF6: =VLOOKUP(AS6,Leyenda!$B$70:$D$75,3,FALSE) -> 15 | BG6: =1.5*BA6+(V6*0.5) -> 0 | BH6: =VLOOKUP(AM6,Leyenda!$B$4:$E$10,4,FALSE) -> 0 | BI6: =IF(Z6="",ROUND(IF(Z6<=50,5,IF(Z6>=3000,30,6.038*LN(Z6)-19.63)),0),ROUND(IF(Z6<=50,5,IF(Z6>=3000,30,6.038*LN(Z6)-19.63)),0)) -> 5 | BJ6: =ROUND(-0.0002*POWER(V6,2)+0.2197*V6,0) -> 0 | BK6: =+VLOOKUP('2. Logging Brejo Seco'!AP6,Leyenda!$B$47:$E$51,4,FALSE) -> 0 | BL6: =+VLOOKUP('2. Logging Brejo Seco'!AQ6,Leyenda!$B$55:$E$59,4,FALSE) -> 0 | BM6: =+VLOOKUP('2. Logging Brejo Seco'!AR6,Leyenda!$B$63:$E$67,3,FALSE) -> 0 | BN6: =+VLOOKUP('2. Logging Brejo Seco'!AO6,Leyenda!$B$39:$E$43,4,FALSE) -> 0 | BO6: =+VLOOKUP('2. Logging Brejo Seco'!AN6,Leyenda!$B$30:$E$34,4,FALSE) -> 0 | BP6: =VLOOKUP(AS6,Leyenda!$B$71:$E$75,4,FALSE) -> 10 | BQ6: =+BH6+BI6+BJ6+BK6+BL6+BM6+BN6+BO6+BP6 -> 15 | BR6: =+BC6+BD6+BB6+BE6+BF6 -> 15 | BS6: =1-N6 -> 0.4 | BT6: Clasificaçao SUCS (Mecanica de Solos)
A7: Brejo Seco | B7: 2024 | C7: PNM | D7: GEOTEC-01 | E7: 60 | F7: 60 | G7: P025_Cob | H7: =+F7 -> 60 | J7: rocha alterada, canga lateritica | K7: =+L6 -> 2 | L7: =+K7+0.5 -> 2.5 | M7: =+L7-K7 -> 0.5 | N7: 0.58 | O7: =1-N7 -> 0.42 | P7: =+M7*N7 -> 0.29 | Q7: =+N7*M7 -> 0.29 | R7: 290 | S7: 1 | T7: =+N7*M7 -> 0.29 | U7: 0 | V7: 0 | Z7: 0 | AA7: 0 | AB7: A1 | AC7: F5 | AD7: C4 | AE7: 20 | AF7: 14.5 | AG7: S2 | AH7: R0 | AI7: =+VLOOKUP(AH7,Leyenda!$O$4:$U$10,6,FALSE) -> 0 | AJ7: =+VLOOKUP(AH7,Leyenda!$O$4:$U$10,7,FALSE) -> No Blasting need | AK7: =+VLOOKUP(AJ7,Leyenda!$U$4:$V$10,2,FALSE) -> 2 | AL7: S2 | AM7: =+AH7 -> R0 | AN7: P5 | AO7: W4 | AP7: A4 | AQ7: G5 | AR7: F4 | AS7: Seco | AV7: =+VLOOKUP(AN7,Leyenda!$B$30:$E$34,3,FALSE) -> 0 | AW7: =+VLOOKUP('2. Logging Brejo Seco'!AO7,Meteorizacion,3,FALSE) -> 0 | AX7: =+VLOOKUP('2. Logging Brejo Seco'!AP7,Apertura,3,FALSE) -> 0 | AY7: =+VLOOKUP('2. Logging Brejo Seco'!AQ7,Leyenda!$B$55:$D$59,3,FALSE) -> 0 | AZ7: =+VLOOKUP('2. Logging Brejo Seco'!AR7,Relleno,3,FALSE) -> 0 | BA7: =+SUM(AV7:AZ7) -> 0 | BB7: =ROUND(-0.0002*POWER(V7,2)+0.2197*V7,0) -> 0 | BC7: =VLOOKUP(AM7,Leyenda!$B$4:$D$10,3,FALSE) -> 0 | BD7: =IF(Z7="",ROUND((IF(Z7<=400,1.5478*POWER(Z7,0.3351),-2*POWER(10,-6)*POWER(Z7,2)+0.0091*Z7+8.1704)),0),ROUND((IF(Z7<=400,1.5478*POWER(Z7,0.3351),-2*POWER(10,-6)*POWER(Z7,2)+0.0091*Z7+8.1704)),0)) -> 0 | BE7: =+BA7 -> 0 | BF7: =VLOOKUP(AS7,Leyenda!$B$70:$D$75,3,FALSE) -> 15 | BG7: =1.5*BA7+(V7*0.5) -> 0 | BH7: =VLOOKUP(AM7,Leyenda!$B$4:$E$10,4,FALSE) -> 0 | BI7: =IF(Z7="",ROUND(IF(Z7<=50,5,IF(Z7>=3000,30,6.038*LN(Z7)-19.63)),0),ROUND(IF(Z7<=50,5,IF(Z7>=3000,30,6.038*LN(Z7)-19.63)),0)) -> 5 | BJ7: =ROUND(-0.0002*POWER(V7,2)+0.2197*V7,0) -> 0 | BK7: =+VLOOKUP('2. Logging Brejo Seco'!AP7,Leyenda!$B$47:$E$51,4,FALSE) -> 0 | BL7: =+VLOOKUP('2. Logging Brejo Seco'!AQ7,Leyenda!$B$55:$E$59,4,FALSE) -> 0 | BM7: =+VLOOKUP('2. Logging Brejo Seco'!AR7,Leyenda!$B$63:$E$67,3,FALSE) -> 0 | BN7: =+VLOOKUP('2. Logging Brejo Seco'!AO7,Leyenda!$B$39:$E$43,4,FALSE) -> 0 | BO7: =+VLOOKUP('2. Logging Brejo Seco'!AN7,Leyenda!$B$30:$E$34,4,FALSE) -> 0 | BP7: =VLOOKUP(AS7,Leyenda!$B$71:$E$75,4,FALSE) -> 10 | BQ7: =+BH7+BI7+BJ7+BK7+BL7+BM7+BN7+BO7+BP7 -> 15 | BR7: =+BC7+BD7+BB7+BE7+BF7 -> 15 | BS7: =1-N7 -> 0.42 | BT7: Clasificaçao SUCS (Mecanica de Solos)
A8: Brejo Seco | B8: 2024 | C8: PNM | D8: GEOTEC-01 | E8: 60 | F8: 60 | G8: P025_Cob | H8: =+F8 -> 60 | J8: rocha alterada, canga lateritica | K8: =+L7 -> 2.5 | L8: =+K8+0.5 -> 3 | M8: =+L8-K8 -> 0.5 | N8: 0.8 | O8: =1-N8 -> 0.2 | P8: =+M8*N8 -> 0.4 | Q8: =+N8*M8 -> 0.4 | R8: 80 | S8: 5 | T8: =+N8*M8 -> 0.4 | U8: 0 | V8: 0 | Z8: 0 | AA8: 50 | AB8: A1 | AC8: F5 | AD8: C4 | AE8: 20 | AF8: 20 | AG8: S2 | AH8: R0 | AI8: =+VLOOKUP(AH8,Leyenda!$O$4:$U$10,6,FALSE) -> 0 | AJ8: =+VLOOKUP(AH8,Leyenda!$O$4:$U$10,7,FALSE) -> No Blasting need | AK8: =+VLOOKUP(AJ8,Leyenda!$U$4:$V$10,2,FALSE) -> 2 | AL8: S2 | AM8: =+AH8 -> R0 | AN8: P5 | AO8: W4 | AP8: A4 | AQ8: G5 | AR8: F4 | AS8: Seco | AV8: =+VLOOKUP(AN8,Leyenda!$B$30:$E$34,3,FALSE) -> 0 | AW8: =+VLOOKUP('2. Logging Brejo Seco'!AO8,Meteorizacion,3,FALSE) -> 0 | AX8: =+VLOOKUP('2. Logging Brejo Seco'!AP8,Apertura,3,FALSE) -> 0 | AY8: =+VLOOKUP('2. Logging Brejo Seco'!AQ8,Leyenda!$B$55:$D$59,3,FALSE) -> 0 | AZ8: =+VLOOKUP('2. Logging Brejo Seco'!AR8,Relleno,3,FALSE) -> 0 | BA8: =+SUM(AV8:AZ8) -> 0 | BB8: =ROUND(-0.0002*POWER(V8,2)+0.2197*V8,0) -> 0 | BC8: =VLOOKUP(AM8,Leyenda!$B$4:$D$10,3,FALSE) -> 0 | BD8: =IF(Z8="",ROUND((IF(Z8<=400,1.5478*POWER(Z8,0.3351),-2*POWER(10,-6)*POWER(Z8,2)+0.0091*Z8+8.1704)),0),ROUND((IF(Z8<=400,1.5478*POWER(Z8,0.3351),-2*POWER(10,-6)*POWER(Z8,2)+0.0091*Z8+8.1704)),0)) -> 0 | BE8: =+BA8 -> 0 | BF8: =VLOOKUP(AS8,Leyenda!$B$70:$D$75,3,FALSE) -> 15 | BG8: =1.5*BA8+(V8*0.5) -> 0 | BH8: =VLOOKUP(AM8,Leyenda!$B$4:$E$10,4,FALSE) -> 0 | BI8: =IF(Z8="",ROUND(IF(Z8<=50,5,IF(Z8>=3000,30,6.038*LN(Z8)-19.63)),0),ROUND(IF(Z8<=50,5,IF(Z8>=3000,30,6.038*LN(Z8)-19.63)),0)) -> 5 | BJ8: =ROUND(-0.0002*POWER(V8,2)+0.2197*V8,0) -> 0 | BK8: =+VLOOKUP('2. Logging Brejo Seco'!AP8,Leyenda!$B$47:$E$51,4,FALSE) -> 0 | BL8: =+VLOOKUP('2. Logging Brejo Seco'!AQ8,Leyenda!$B$55:$E$59,4,FALSE) -> 0 | BM8: =+VLOOKUP('2. Logging Brejo Seco'!AR8,Leyenda!$B$63:$E$67,3,FALSE) -> 0 | BN8: =+VLOOKUP('2. Logging Brejo Seco'!AO8,Leyenda!$B$39:$E$43,4,FALSE) -> 0 | BO8: =+VLOOKUP('2. Logging Brejo Seco'!AN8,Leyenda!$B$30:$E$34,4,FALSE) -> 0 | BP8: =VLOOKUP(AS8,Leyenda!$B$71:$E$75,4,FALSE) -> 10 | BQ8: =+BH8+BI8+BJ8+BK8+BL8+BM8+BN8+BO8+BP8 -> 15 | BR8: =+BC8+BD8+BB8+BE8+BF8 -> 15 | BS8: =1-N8 -> 0.2 | BT8: Clasificaçao SUCS (Mecanica de Solos)
A9: Brejo Seco | B9: 2024 | C9: PNM | D9: GEOTEC-01 | E9: 40 | F9: 40 | G9: P025_Silica_Zone | H9: =+F9 -> 40 | J9: rocha alterada, canga lateritica | K9: =+L8 -> 3 | L9: =+K9+0.5 -> 3.5 | M9: =+L9-K9 -> 0.5 | N9: 0.8 | O9: =1-N9 -> 0.2 | P9: =+M9*N9 -> 0.4 | Q9: =+N9*M9 -> 0.4 | R9: 80 | S9: 5 | T9: 0.38 | U9: 0.3 | V9: =+U9/M9*100 -> 60 | W9: 1 | X9: 2 | Y9: =+W9+X9 -> 3 | Z9: =+IF(T9=0,"",(T9*1000)/Y9) -> 126.66667 | AA9: 64 | AB9: A1 | AC9: F2 | AD9: C4 | AE9: 5 | AF9: 80 | AG9: R3 | AH9: =+AG9 -> R3 | AI9: =+VLOOKUP(AH9,Leyenda!$O$4:$U$10,6,FALSE) -> 0,35-0,50 | AJ9: =+VLOOKUP(AH9,Leyenda!$O$4:$U$10,7,FALSE) -> Easy to blast | AK9: =+VLOOKUP(AJ9,Leyenda!$U$4:$V$10,2,FALSE) -> 3 | AL9: R3 | AM9: =+AH9 -> R3 | AN9: P3 | AO9: W3 | AP9: A3 | AQ9: G3 | AR9: F1 | AS9: Seco | AT9: Calcedonia Cuarzo | AV9: =+VLOOKUP(AN9,Leyenda!$B$30:$E$34,3,FALSE) -> 2 | AW9: =+VLOOKUP('2. Logging Brejo Seco'!AO9,Meteorizacion,3,FALSE) -> 1 | AX9: =+VLOOKUP('2. Logging Brejo Seco'!AP9,Apertura,3,FALSE) -> 1 | AY9: =+VLOOKUP('2. Logging Brejo Seco'!AQ9,Leyenda!$B$55:$D$59,3,FALSE) -> 3 | AZ9: =+VLOOKUP('2. Logging Brejo Seco'!AR9,Relleno,3,FALSE) -> 4 | BA9: =+SUM(AV9:AZ9) -> 11 | BB9: =ROUND(-0.0002*POWER(V9,2)+0.2197*V9,0) -> 12 | BC9: =VLOOKUP(AM9,Leyenda!$B$4:$D$10,3,FALSE) -> 4 | BD9: =IF(Z9="",ROUND((IF(Z9<=400,1.5478*POWER(Z9,0.3351),-2*POWER(10,-6)*POWER(Z9,2)+0.0091*Z9+8.1704)),0),ROUND((IF(Z9<=400,1.5478*POWER(Z9,0.3351),-2*POWER(10,-6)*POWER(Z9,2)+0.0091*Z9+8.1704)),0)) -> 8 | BE9: =+BA9 -> 11 | BF9: =VLOOKUP(AS9,Leyenda!$B$70:$D$75,3,FALSE) -> 15 | BG9: =1.5*BA9+(V9*0.5) -> 46.5 | BH9: =VLOOKUP(AM9,Leyenda!$B$4:$E$10,4,FALSE) -> 4 | BI9: =IF(Z9="",ROUND(IF(Z9<=50,5,IF(Z9>=3000,30,6.038*LN(Z9)-19.63)),0),ROUND(IF(Z9<=50,5,IF(Z9>=3000,30,6.038*LN(Z9)-19.63)),0)) -> 10 | BJ9: =ROUND(-0.0002*POWER(V9,2)+0.2197*V9,0) -> 12 | BK9: =+VLOOKUP('2. Logging Brejo Seco'!AP9,Leyenda!$B$47:$E$51,4,FALSE) -> 1 | BL9: =+VLOOKUP('2. Logging Brejo Seco'!AQ9,Leyenda!$B$55:$E$59,4,FALSE) -> 3 | BM9: =+VLOOKUP('2. Logging Brejo Seco'!AR9,Leyenda!$B$63:$E$67,3,FALSE) -> 4 | BN9: =+VLOOKUP('2. Logging Brejo Seco'!AO9,Leyenda!$B$39:$E$43,4,FALSE) -> 1 | BO9: =+VLOOKUP('2. Logging Brejo Seco'!AN9,Leyenda!$B$30:$E$34,4,FALSE) -> 3 | BP9: =VLOOKUP(AS9,Leyenda!$B$71:$E$75,4,FALSE) -> 10 | BQ9: =+BH9+BI9+BJ9+BK9+BL9+BM9+BN9+BO9+BP9 -> 48 | BR9: =+BC9+BD9+BB9+BE9+BF9 -> 50 | BS9: =1-N9 -> 0.2
A10: Brejo Seco | B10: 2024 | C10: PNM | D10: GEOTEC-01 | E10: 40 | F10: 40 | G10: P025_Silica_Zone | H10: =+F10 -> 40 | J10: rocha alterada, canga lateritica | K10: =+L9 -> 3.5 | L10: =+K10+0.5 -> 4 | M10: =+L10-K10 -> 0.5 | N10: 0.76 | O10: =1-N10 -> 0.24 | P10: =+M10*N10 -> 0.38 | Q10: =+N10*M10 -> 0.38 | R10: 76 | S10: 5 | T10: 0.42 | U10: 0.5 | V10: =+U10/M10*100 -> 100 | W10: 1 | Y10: 1 | Z10: =+IF(T10=0,"",(T10*1000)/Y10) -> 420 | AA10: 22 | AB10: A1 | AC10: F2 | AD10: C4 | AE10: 5 | AF10: 76 | AG10: R4 | AH10: =+AG10 -> R4 | AI10: =+VLOOKUP(AH10,Leyenda!$O$4:$U$10,6,FALSE) -> 0,50-0,80 | AJ10: =+VLOOKUP(AH10,Leyenda!$O$4:$U$10,7,FALSE) -> Fairly easy to blast | AK10: =+VLOOKUP(AJ10,Leyenda!$U$4:$V$10,2,FALSE) -> 4 | AL10: R4 | AM10: =+AH10 -> R4 | AN10: P3 | AO10: W3 | AP10: A3 | AQ10: G3 | AR10: F2 | AS10: Seco | AT10: Calcedonia Cuarzo | AV10: =+VLOOKUP(AN10,Leyenda!$B$30:$E$34,3,FALSE) -> 2 | AW10: =+VLOOKUP('2. Logging Brejo Seco'!AO10,Meteorizacion,3,FALSE) -> 1 | AX10: =+VLOOKUP('2. Logging Brejo Seco'!AP10,Apertura,3,FALSE) -> 1 | AY10: =+VLOOKUP('2. Logging Brejo Seco'!AQ10,Leyenda!$B$55:$D$59,3,FALSE) -> 3 | AZ10: =+VLOOKUP('2. Logging Brejo Seco'!AR10,Relleno,3,FALSE) -> 2 | BA10: =+SUM(AV10:AZ10) -> 9 | BB10: =ROUND(-0.0002*POWER(V10,2)+0.2197*V10,0) -> 20 | BC10: =VLOOKUP(AM10,Leyenda!$B$4:$D$10,3,FALSE) -> 7 | BD10: =IF(Z10="",ROUND((IF(Z10<=400,1.5478*POWER(Z10,0.3351),-2*POWER(10,-6)*POWER(Z10,2)+0.0091*Z10+8.1704)),0),ROUND((IF(Z10<=400,1.5478*POWER(Z10,0.3351),-2*POWER(10,-6)*POWER(Z10,2)+0.0091*Z10+8.1704)),0)) -> 12 | BE10: =+BA10 -> 9 | BF10: =VLOOKUP(AS10,Leyenda!$B$70:$D$75,3,FALSE) -> 15 | BG10: =1.5*BA10+(V10*0.5) -> 63.5 | BH10: =VLOOKUP(AM10,Leyenda!$B$4:$E$10,4,FALSE) -> 7 | BI10: =IF(Z10="",ROUND(IF(Z10<=50,5,IF(Z10>=3000,30,6.038*LN(Z10)-19.63)),0),ROUND(IF(Z10<=50,5,IF(Z10>=3000,30,6.038*LN(Z10)-19.63)),0)) -> 17 | BJ10: =ROUND(-0.0002*POWER(V10,2)+0.2197*V10,0) -> 20 | BK10: =+VLOOKUP('2. Logging Brejo Seco'!AP10,Leyenda!$B$47:$E$51,4,FALSE) -> 1 | BL10: =+VLOOKUP('2. Logging Brejo Seco'!AQ10,Leyenda!$B$55:$E$59,4,FALSE) -> 3 | BM10: =+VLOOKUP('2. Logging Brejo Seco'!AR10,Leyenda!$B$63:$E$67,3,FALSE) -> 2 | BN10: =+VLOOKUP('2. Logging Brejo Seco'!AO10,Leyenda!$B$39:$E$43,4,FALSE) -> 1 | BO10: =+VLOOKUP('2. Logging Brejo Seco'!AN10,Leyenda!$B$30:$E$34,4,FALSE) -> 3 | BP10: =VLOOKUP(AS10,Leyenda!$B$71:$E$75,4,FALSE) -> 10 | BQ10: =+BH10+BI10+BJ10+BK10+BL10+BM10+BN10+BO10+BP10 -> 64 | BR10: =+BC10+BD10+BB10+BE10+BF10 -> 63 | BS10: =1-N10 -> 0.24
A11: Brejo Seco | B11: 2024 | C11: PNM | D11: GEOTEC-01 | E11: 40 | F11: 40 | G11: P025_Silica_Zone | H11: =+F11 -> 40 | J11: rocha alterada, canga lateritica | K11: =+L10 -> 4 | L11: =+K11+0.5 -> 4.5 | M11: =+L11-K11 -> 0.5 | N11: 0.86 | O11: =1-N11 -> 0.14 | P11: =+M11*N11 -> 0.43 | Q11: =+N11*M11 -> 0.43 | R11: 21.5 | S11: 20 | T11: 0.19 | U11: 0 | V11: =+U11/M11*100 -> 0 | W11: 0 | X11: 10 | Y11: =+W11+X11 -> 10 | Z11: =+IF(T11=0,"",(T11*1000)/Y11) -> 19 | AA11: 0 | AB11: A1 | AC11: F5 | AD11: C4 | AE11: 20 | AF11: 21.5 | AG11: R3 | AH11: =+AG11 -> R3 | AI11: =+VLOOKUP(AH11,Leyenda!$O$4:$U$10,6,FALSE) -> 0,35-0,50 | AJ11: =+VLOOKUP(AH11,Leyenda!$O$4:$U$10,7,FALSE) -> Easy to blast | AK11: =+VLOOKUP(AJ11,Leyenda!$U$4:$V$10,2,FALSE) -> 3 | AL11: R3 | AM11: =+AH11 -> R3 | AN11: P3 | AO11: W4 | AP11: A4 | AQ11: G5 | AR11: F4 | AS11: Seco | AT11: Zona completamente alterada por pos falha | AV11: =+VLOOKUP(AN11,Leyenda!$B$30:$E$34,3,FALSE) -> 2 | AW11: =+VLOOKUP('2. Logging Brejo Seco'!AO11,Meteorizacion,3,FALSE) -> 0 | AX11: =+VLOOKUP('2. Logging Brejo Seco'!AP11,Apertura,3,FALSE) -> 0 | AY11: =+VLOOKUP('2. Logging Brejo Seco'!AQ11,Leyenda!$B$55:$D$59,3,FALSE) -> 0 | AZ11: =+VLOOKUP('2. Logging Brejo Seco'!AR11,Relleno,3,FALSE) -> 0 | BA11: =+SUM(AV11:AZ11) -> 2 | BB11: =ROUND(-0.0002*POWER(V11,2)+0.2197*V11,0) -> 0 | BC11: =VLOOKUP(AM11,Leyenda!$B$4:$D$10,3,FALSE) -> 4 | BD11: =IF(Z11="",ROUND((IF(Z11<=400,1.5478*POWER(Z11,0.3351),-2*POWER(10,-6)*POWER(Z11,2)+0.0091*Z11+8.1704)),0),ROUND((IF(Z11<=400,1.5478*POWER(Z11,0.3351),-2*POWER(10,-6)*POWER(Z11,2)+0.0091*Z11+8.1704)),0)) -> 4 | BE11: =+BA11 -> 2 | BF11: =VLOOKUP(AS11,Leyenda!$B$70:$D$75,3,FALSE) -> 15 | BG11: =1.5*BA11+(V11*0.5) -> 3 | BH11: =VLOOKUP(AM11,Leyenda!$B$4:$E$10,4,FALSE) -> 4 | BI11: =IF(Z11="",ROUND(IF(Z11<=50,5,IF(Z11>=3000,30,6.038*LN(Z11)-19.63)),0),ROUND(IF(Z11<=50,5,IF(Z11>=3000,30,6.038*LN(Z11)-19.63)),0)) -> 5 | BJ11: =ROUND(-0.0002*POWER(V11,2)+0.2197*V11,0) -> 0 | BK11: =+VLOOKUP('2. Logging Brejo Seco'!AP11,Leyenda!$B$47:$E$51,4,FALSE) -> 0 | BL11: =+VLOOKUP('2. Logging Brejo Seco'!AQ11,Leyenda!$B$55:$E$59,4,FALSE) -> 0 | BM11: =+VLOOKUP('2. Logging Brejo Seco'!AR11,Leyenda!$B$63:$E$67,3,FALSE) -> 0 | BN11: =+VLOOKUP('2. Logging Brejo Seco'!AO11,Leyenda!$B$39:$E$43,4,FALSE) -> 0 | BO11: =+VLOOKUP('2. Logging Brejo Seco'!AN11,Leyenda!$B$30:$E$34,4,FALSE) -> 3 | BP11: =VLOOKUP(AS11,Leyenda!$B$71:$E$75,4,FALSE) -> 10 | BQ11: =+BH11+BI11+BJ11+BK11+BL11+BM11+BN11+BO11+BP11 -> 22 | BR11: =+BC11+BD11+BB11+BE11+BF11 -> 25 | BS11: =1-N11 -> 0.14
A12: Brejo Seco | B12: 2024 | C12: PNM | D12: GEOTEC-01 | E12: 50 | F12: 50 | G12: P0723_Sap_Fe | H12: =+F12 -> 50 | J12: rocha alterada, canga lateritica | K12: =+L11 -> 4.5 | L12: =+K12+0.5 -> 5 | M12: =+L12-K12 -> 0.5 | N12: 0.38 | O12: =1-N12 -> 0.62 | P12: =+M12*N12 -> 0.19 | Q12: =+N12*M12 -> 0.19 | R12: 190 | S12: 1 | T12: 0.36 | U12: 0.3 | V12: =+U12/M12*100 -> 60 | W12: 2 | Y12: =+W12+X12 -> 2 | Z12: =+IF(T12=0,"",(T12*1000)/Y12) -> 180 | AA12: 64 | AB12: A1 | AC12: F1 | AD12: C4 | AE12: 1 | AF12: 190 | AG12: S6 | AH12: R0 | AI12: =+VLOOKUP(AH12,Leyenda!$O$4:$U$10,6,FALSE) -> 0 | AJ12: =+VLOOKUP(AH12,Leyenda!$O$4:$U$10,7,FALSE) -> No Blasting need | AK12: =+VLOOKUP(AJ12,Leyenda!$U$4:$V$10,2,FALSE) -> 2 | AL12: S6 | AM12: =+AH12 -> R0 | AN12: P3 | AO12: W3 | AP12: A4 | AQ12: G3 | AR12: F2 | AS12: Seco | AT12: Venillas de Calcedonia | AV12: =+VLOOKUP(AN12,Leyenda!$B$30:$E$34,3,FALSE) -> 2 | AW12: =+VLOOKUP('2. Logging Brejo Seco'!AO12,Meteorizacion,3,FALSE) -> 1 | AX12: =+VLOOKUP('2. Logging Brejo Seco'!AP12,Apertura,3,FALSE) -> 0 | AY12: =+VLOOKUP('2. Logging Brejo Seco'!AQ12,Leyenda!$B$55:$D$59,3,FALSE) -> 3 | AZ12: =+VLOOKUP('2. Logging Brejo Seco'!AR12,Relleno,3,FALSE) -> 2 | BA12: =+SUM(AV12:AZ12) -> 8 | BB12: =ROUND(-0.0002*POWER(V12,2)+0.2197*V12,0) -> 12 | BC12: =VLOOKUP(AM12,Leyenda!$B$4:$D$10,3,FALSE) -> 0 | BD12: =IF(Z12="",ROUND((IF(Z12<=400,1.5478*POWER(Z12,0.3351),-2*POWER(10,-6)*POWER(Z12,2)+0.0091*Z12+8.1704)),0),ROUND((IF(Z12<=400,1.5478*POWER(Z12,0.3351),-2*POWER(10,-6)*POWER(Z12,2)+0.0091*Z12+8.1704)),0)) -> 9 | BE12: =+BA12 -> 8 | BF12: =VLOOKUP(AS12,Leyenda!$B$70:$D$75,3,FALSE) -> 15 | BG12: =1.5*BA12+(V12*0.5) -> 42 | BH12: =VLOOKUP(AM12,Leyenda!$B$4:$E$10,4,FALSE) -> 0 | BI12: =IF(Z12="",ROUND(IF(Z12<=50,5,IF(Z12>=3000,30,6.038*LN(Z12)-19.63)),0),ROUND(IF(Z12<=50,5,IF(Z12>=3000,30,6.038*LN(Z12)-19.63)),0)) -> 12 | BJ12: =ROUND(-0.0002*POWER(V12,2)+0.2197*V12,0) -> 12 | BK12: =+VLOOKUP('2. Logging Brejo Seco'!AP12,Leyenda!$B$47:$E$51,4,FALSE) -> 0 | BL12: =+VLOOKUP('2. Logging Brejo Seco'!AQ12,Leyenda!$B$55:$E$59,4,FALSE) -> 3 | BM12: =+VLOOKUP('2. Logging Brejo Seco'!AR12,Leyenda!$B$63:$E$67,3,FALSE) -> 2 | BN12: =+VLOOKUP('2. Logging Brejo Seco'!AO12,Leyenda!$B$39:$E$43,4,FALSE) -> 1 | BO12: =+VLOOKUP('2. Logging Brejo Seco'!AN12,Leyenda!$B$30:$E$34,4,FALSE) -> 3 | BP12: =VLOOKUP(AS12,Leyenda!$B$71:$E$75,4,FALSE) -> 10 | BQ12: =+BH12+BI12+BJ12+BK12+BL12+BM12+BN12+BO12+BP12 -> 43 | BR12: =+BC12+BD12+BB12+BE12+BF12 -> 44 | BS12: =1-N12 -> 0.62 | BT12: Clasificaçao SUCS (Mecanica de Solos)
A13: Brejo Seco | B13: 2024 | C13: PNM | D13: GEOTEC-01 | E13: 50 | F13: 50 | G13: P0723_Sap_Fe | H13: =+F13 -> 50 | J13: rocha alterada, canga lateritica | K13: =+L12 -> 5 | L13: =+K13+0.5 -> 5.5 | M13: =+L13-K13 -> 0.5 | N13: 0.82 | O13: =1-N13 -> 0.18 | P13: =+M13*N13 -> 0.41 | Q13: =+N13*M13 -> 0.41 | R13: 82 | S13: 5 | T13: 0.39 | U13: 0.13 | V13: =+U13/M13*100 -> 26 | W13: 5 | Y13: =+W13+X13 -> 5 | Z13: =+IF(T13=0,"",(T13*1000)/Y13) -> 78 | AA13: 32 | AB13: A1 | AC13: F2 | AD13: C4 | AE13: 5 | AF13: 82 | AG13: S6 | AH13: R0 | AI13: =+VLOOKUP(AH13,Leyenda!$O$4:$U$10,6,FALSE) -> 0 | AJ13: =+VLOOKUP(AH13,Leyenda!$O$4:$U$10,7,FALSE) -> No Blasting need | AK13: =+VLOOKUP(AJ13,Leyenda!$U$4:$V$10,2,FALSE) -> 2 | AL13: S6 | AM13: =+AH13 -> R0 | AN13: P3 | AO13: W3 | AP13: A4 | AQ13: G4 | AR13: F3 | AS13: Seco | AT13: Solo Limonita | AV13: =+VLOOKUP(AN13,Leyenda!$B$30:$E$34,3,FALSE) -> 2 | AW13: =+VLOOKUP('2. Logging Brejo Seco'!AO13,Meteorizacion,3,FALSE) -> 1 | AX13: =+VLOOKUP('2. Logging Brejo Seco'!AP13,Apertura,3,FALSE) -> 0 | AY13: =+VLOOKUP('2. Logging Brejo Seco'!AQ13,Leyenda!$B$55:$D$59,3,FALSE) -> 1 | AZ13: =+VLOOKUP('2. Logging Brejo Seco'!AR13,Relleno,3,FALSE) -> 2 | BA13: =+SUM(AV13:AZ13) -> 6 | BB13: =ROUND(-0.0002*POWER(V13,2)+0.2197*V13,0) -> 6 | BC13: =VLOOKUP(AM13,Leyenda!$B$4:$D$10,3,FALSE) -> 0 | BD13: =IF(Z13="",ROUND((IF(Z13<=400,1.5478*POWER(Z13,0.3351),-2*POWER(10,-6)*POWER(Z13,2)+0.0091*Z13+8.1704)),0),ROUND((IF(Z13<=400,1.5478*POWER(Z13,0.3351),-2*POWER(10,-6)*POWER(Z13,2)+0.0091*Z13+8.1704)),0)) -> 7 | BE13: =+BA13 -> 6 | BF13: =VLOOKUP(AS13,Leyenda!$B$70:$D$75,3,FALSE) -> 15 | BG13: =1.5*BA13+(V13*0.5) -> 22 | BH13: =VLOOKUP(AM13,Leyenda!$B$4:$E$10,4,FALSE) -> 0 | BI13: =IF(Z13="",ROUND(IF(Z13<=50,5,IF(Z13>=3000,30,6.038*LN(Z13)-19.63)),0),ROUND(IF(Z13<=50,5,IF(Z13>=3000,30,6.038*LN(Z13)-19.63)),0)) -> 7 | BJ13: =ROUND(-0.0002*POWER(V13,2)+0.2197*V13,0) -> 6 | BK13: =+VLOOKUP('2. Logging Brejo Seco'!AP13,Leyenda!$B$47:$E$51,4,FALSE) -> 0 | BL13: =+VLOOKUP('2. Logging Brejo Seco'!AQ13,Leyenda!$B$55:$E$59,4,FALSE) -> 1 | BM13: =+VLOOKUP('2. Logging Brejo Seco'!AR13,Leyenda!$B$63:$E$67,3,FALSE) -> 2 | BN13: =+VLOOKUP('2. Logging Brejo Seco'!AO13,Leyenda!$B$39:$E$43,4,FALSE) -> 1 | BO13: =+VLOOKUP('2. Logging Brejo Seco'!AN13,Leyenda!$B$30:$E$34,4,FALSE) -> 3 | BP13: =VLOOKUP(AS13,Leyenda!$B$71:$E$75,4,FALSE) -> 10 | BQ13: =+BH13+BI13+BJ13+BK13+BL13+BM13+BN13+BO13+BP13 -> 30 | BR13: =+BC13+BD13+BB13+BE13+BF13 -> 34 | BS13: =1-N13 -> 0.18 | BT13: Clasificaçao SUCS (Mecanica de Solos)
A14: Brejo Seco | B14: 2024 | C14: PNM | D14: GEOTEC-01 | E14: 50 | F14: 50 | G14: P0723_Sap_Fe | H14: =+F14 -> 50 | J14: rocha alterada, canga lateritica | K14: =+L13 -> 5.5 | L14: =+K14+0.5 -> 6 | M14: =+L14-K14 -> 0.5 | N14: 0.82 | O14: =1-N14 -> 0.18 | P14: =+M14*N14 -> 0.41 | Q14: =+N14*M14 -> 0.41 | R14: 410 | S14: 1 | T14: 0.35 | U14: 0.16 | V14: =+U14/M14*100 -> 32 | W14: 4 | Y14: =+W14+X14 -> 4 | Z14: =+IF(T14=0,"",(T14*1000)/Y14) -> 87.5 | AA14: 38 | AB14: A1 | AC14: F1 | AD14: C4 | AE14: 1 | AF14: 410 | AG14: S5 | AH14: R0 | AI14: =+VLOOKUP(AH14,Leyenda!$O$4:$U$10,6,FALSE) -> 0 | AJ14: =+VLOOKUP(AH14,Leyenda!$O$4:$U$10,7,FALSE) -> No Blasting need | AK14: =+VLOOKUP(AJ14,Leyenda!$U$4:$V$10,2,FALSE) -> 2 | AL14: S5 | AM14: =+AH14 -> R0 | AN14: P3 | AO14: W2 | AP14: A4 | AQ14: G4 | AR14: F3 | AS14: Seco | AT14: Solo Limonita | AV14: =+VLOOKUP(AN14,Leyenda!$B$30:$E$34,3,FALSE) -> 2 | AW14: =+VLOOKUP('2. Logging Brejo Seco'!AO14,Meteorizacion,3,FALSE) -> 3 | AX14: =+VLOOKUP('2. Logging Brejo Seco'!AP14,Apertura,3,FALSE) -> 0 | AY14: =+VLOOKUP('2. Logging Brejo Seco'!AQ14,Leyenda!$B$55:$D$59,3,FALSE) -> 1 | AZ14: =+VLOOKUP('2. Logging Brejo Seco'!AR14,Relleno,3,FALSE) -> 2 | BA14: =+SUM(AV14:AZ14) -> 8 | BB14: =ROUND(-0.0002*POWER(V14,2)+0.2197*V14,0) -> 7 | BC14: =VLOOKUP(AM14,Leyenda!$B$4:$D$10,3,FALSE) -> 0 | BD14: =IF(Z14="",ROUND((IF(Z14<=400,1.5478*POWER(Z14,0.3351),-2*POWER(10,-6)*POWER(Z14,2)+0.0091*Z14+8.1704)),0),ROUND((IF(Z14<=400,1.5478*POWER(Z14,0.3351),-2*POWER(10,-6)*POWER(Z14,2)+0.0091*Z14+8.1704)),0)) -> 7 | BE14: =+BA14 -> 8 | BF14: =VLOOKUP(AS14,Leyenda!$B$70:$D$75,3,FALSE) -> 15 | BG14: =1.5*BA14+(V14*0.5) -> 28 | BH14: =VLOOKUP(AM14,Leyenda!$B$4:$E$10,4,FALSE) -> 0 | BI14: =IF(Z14="",ROUND(IF(Z14<=50,5,IF(Z14>=3000,30,6.038*LN(Z14)-19.63)),0),ROUND(IF(Z14<=50,5,IF(Z14>=3000,30,6.038*LN(Z14)-19.63)),0)) -> 7 | BJ14: =ROUND(-0.0002*POWER(V14,2)+0.2197*V14,0) -> 7 | BK14: =+VLOOKUP('2. Logging Brejo Seco'!AP14,Leyenda!$B$47:$E$51,4,FALSE) -> 0 | BL14: =+VLOOKUP('2. Logging Brejo Seco'!AQ14,Leyenda!$B$55:$E$59,4,FALSE) -> 1 | BM14: =+VLOOKUP('2. Logging Brejo Seco'!AR14,Leyenda!$B$63:$E$67,3,FALSE) -> 2 | BN14: =+VLOOKUP('2. Logging Brejo Seco'!AO14,Leyenda!$B$39:$E$43,4,FALSE) -> 3 | BO14: =+VLOOKUP('2. Logging Brejo Seco'!AN14,Leyenda!$B$30:$E$34,4,FALSE) -> 3 | BP14: =VLOOKUP(AS14,Leyenda!$B$71:$E$75,4,FALSE) -> 10 | BQ14: =+BH14+BI14+BJ14+BK14+BL14+BM14+BN14+BO14+BP14 -> 33 | BR14: =+BC14+BD14+BB14+BE14+BF14 -> 37 | BS14: =1-N14 -> 0.18 | BT14: Clasificaçao SUCS (Mecanica de Solos)
A15: Brejo Seco | B15: 2024 | C15: PNM | D15: GEOTEC-01 | E15: 50 | F15: 50 | G15: P0723_Sap_Fe | H15: =+F15 -> 50 | J15: rocha alterada, canga lateritica | K15: =+L14 -> 6 | L15: =+K15+0.5 -> 6.5 | M15: =+L15-K15 -> 0.5 | N15: 0.74 | O15: =1-N15 -> 0.26 | P15: =+M15*N15 -> 0.37 | Q15: =+N15*M15 -> 0.37 | R15: 18.5 | S15: 20 | T15: 0.23 | U15: 0 | V15: =+U15/M15*100 -> 0 | W15: 15 | Y15: =+W15+X15 -> 15 | Z15: =+IF(T15=0,"",(T15*1000)/Y15) -> 15.333333 | AA15: 0 | AB15: A1 | AC15: F5 | AD15: C4 | AE15: 20 | AF15: 18.5 | AG15: S3 | AH15: R0 | AI15: =+VLOOKUP(AH15,Leyenda!$O$4:$U$10,6,FALSE) -> 0 | AJ15: =+VLOOKUP(AH15,Leyenda!$O$4:$U$10,7,FALSE) -> No Blasting need | AK15: =+VLOOKUP(AJ15,Leyenda!$U$4:$V$10,2,FALSE) -> 2 | AL15: S3 | AM15: =+AH15 -> R0 | AN15: P3 | AO15: W4 | AP15: A4 | AQ15: G5 | AR15: F3 | AS15: Seco | AT15: Falla | AV15: =+VLOOKUP(AN15,Leyenda!$B$30:$E$34,3,FALSE) -> 2 | AW15: =+VLOOKUP('2. Logging Brejo Seco'!AO15,Meteorizacion,3,FALSE) -> 0 | AX15: =+VLOOKUP('2. Logging Brejo Seco'!AP15,Apertura,3,FALSE) -> 0 | AY15: =+VLOOKUP('2. Logging Brejo Seco'!AQ15,Leyenda!$B$55:$D$59,3,FALSE) -> 0 | AZ15: =+VLOOKUP('2. Logging Brejo Seco'!AR15,Relleno,3,FALSE) -> 2 | BA15: =+SUM(AV15:AZ15) -> 4 | BB15: =ROUND(-0.0002*POWER(V15,2)+0.2197*V15,0) -> 0 | BC15: =VLOOKUP(AM15,Leyenda!$B$4:$D$10,3,FALSE) -> 0 | BD15: =IF(Z15="",ROUND((IF(Z15<=400,1.5478*POWER(Z15,0.3351),-2*POWER(10,-6)*POWER(Z15,2)+0.0091*Z15+8.1704)),0),ROUND((IF(Z15<=400,1.5478*POWER(Z15,0.3351),-2*POWER(10,-6)*POWER(Z15,2)+0.0091*Z15+8.1704)),0)) -> 4 | BE15: =+BA15 -> 4 | BF15: =VLOOKUP(AS15,Leyenda!$B$70:$D$75,3,FALSE) -> 15 | BG15: =1.5*BA15+(V15*0.5) -> 6 | BH15: =VLOOKUP(AM15,Leyenda!$B$4:$E$10,4,FALSE) -> 0 | BI15: =IF(Z15="",ROUND(IF(Z15<=50,5,IF(Z15>=3000,30,6.038*LN(Z15)-19.63)),0),ROUND(IF(Z15<=50,5,IF(Z15>=3000,30,6.038*LN(Z15)-19.63)),0)) -> 5 | BJ15: =ROUND(-0.0002*POWER(V15,2)+0.2197*V15,0) -> 0 | BK15: =+VLOOKUP('2. Logging Brejo Seco'!AP15,Leyenda!$B$47:$E$51,4,FALSE) -> 0 | BL15: =+VLOOKUP('2. Logging Brejo Seco'!AQ15,Leyenda!$B$55:$E$59,4,FALSE) -> 0 | BM15: =+VLOOKUP('2. Logging Brejo Seco'!AR15,Leyenda!$B$63:$E$67,3,FALSE) -> 2 | BN15: =+VLOOKUP('2. Logging Brejo Seco'!AO15,Leyenda!$B$39:$E$43,4,FALSE) -> 0 | BO15: =+VLOOKUP('2. Logging Brejo Seco'!AN15,Leyenda!$B$30:$E$34,4,FALSE) -> 3 | BP15: =VLOOKUP(AS15,Leyenda!$B$71:$E$75,4,FALSE) -> 10 | BQ15: =+BH15+BI15+BJ15+BK15+BL15+BM15+BN15+BO15+BP15 -> 20 | BR15: =+BC15+BD15+BB15+BE15+BF15 -> 23 | BS15: =1-N15 -> 0.26 | BT15: Clasificaçao SUCS (Mecanica de Solos)
A16: Brejo Seco | B16: 2024 | C16: PNM | D16: GEOTEC-01 | E16: 40 | F16: 40 | G16: P025_Silica_Zone | H16: =+F16 -> 40 | J16: rocha alterada, canga lateritica | K16: =+L15 -> 6.5 | L16: =+K16+0.5 -> 7 | M16: =+L16-K16 -> 0.5 | N16: 0.74 | O16: =1-N16 -> 0.26 | P16: =+M16*N16 -> 0.37 | Q16: =+N16*M16 -> 0.37 | R16: 74 | S16: 5 | T16: 0.46 | U16: 0.11 | V16: =+U16/M16*100 -> 22 | W16: 6 | Y16: =+W16+X16 -> 6 | Z16: =+IF(T16=0,"",(T16*1000)/Y16) -> 76.666667 | AA16: 24 | AB16: A1 | AC16: F2 | AD16: C4 | AE16: 5 | AF16: 74 | AG16: S2 | AH16: R0 | AI16: =+VLOOKUP(AH16,Leyenda!$O$4:$U$10,6,FALSE) -> 0 | AJ16: =+VLOOKUP(AH16,Leyenda!$O$4:$U$10,7,FALSE) -> No Blasting need | AK16: =+VLOOKUP(AJ16,Leyenda!$U$4:$V$10,2,FALSE) -> 2 | AL16: R3 | AM16: =+AH16 -> R0 | AN16: P3 | AO16: W2 | AP16: A4 | AQ16: G4 | AR16: F2 | AS16: Seco | AT16: Venillas de calcedonia | AV16: =+VLOOKUP(AN16,Leyenda!$B$30:$E$34,3,FALSE) -> 2 | AW16: =+VLOOKUP('2. Logging Brejo Seco'!AO16,Meteorizacion,3,FALSE) -> 3 | AX16: =+VLOOKUP('2. Logging Brejo Seco'!AP16,Apertura,3,FALSE) -> 0 | AY16: =+VLOOKUP('2. Logging Brejo Seco'!AQ16,Leyenda!$B$55:$D$59,3,FALSE) -> 1 | AZ16: =+VLOOKUP('2. Logging Brejo Seco'!AR16,Relleno,3,FALSE) -> 2 | BA16: =+SUM(AV16:AZ16) -> 8 | BB16: =ROUND(-0.0002*POWER(V16,2)+0.2197*V16,0) -> 5 | BC16: =VLOOKUP(AM16,Leyenda!$B$4:$D$10,3,FALSE) -> 0 | BD16: =IF(Z16="",ROUND((IF(Z16<=400,1.5478*POWER(Z16,0.3351),-2*POWER(10,-6)*POWER(Z16,2)+0.0091*Z16+8.1704)),0),ROUND((IF(Z16<=400,1.5478*POWER(Z16,0.3351),-2*POWER(10,-6)*POWER(Z16,2)+0.0091*Z16+8.1704)),0)) -> 7 | BE16: =+BA16 -> 8 | BF16: =VLOOKUP(AS16,Leyenda!$B$70:$D$75,3,FALSE) -> 15 | BG16: =1.5*BA16+(V16*0.5) -> 23 | BH16: =VLOOKUP(AM16,Leyenda!$B$4:$E$10,4,FALSE) -> 0 | BI16: =IF(Z16="",ROUND(IF(Z16<=50,5,IF(Z16>=3000,30,6.038*LN(Z16)-19.63)),0),ROUND(IF(Z16<=50,5,IF(Z16>=3000,30,6.038*LN(Z16)-19.63)),0)) -> 7 | BJ16: =ROUND(-0.0002*POWER(V16,2)+0.2197*V16,0) -> 5 | BK16: =+VLOOKUP('2. Logging Brejo Seco'!AP16,Leyenda!$B$47:$E$51,4,FALSE) -> 0 | BL16: =+VLOOKUP('2. Logging Brejo Seco'!AQ16,Leyenda!$B$55:$E$59,4,FALSE) -> 1 | BM16: =+VLOOKUP('2. Logging Brejo Seco'!AR16,Leyenda!$B$63:$E$67,3,FALSE) -> 2 | BN16: =+VLOOKUP('2. Logging Brejo Seco'!AO16,Leyenda!$B$39:$E$43,4,FALSE) -> 3 | BO16: =+VLOOKUP('2. Logging Brejo Seco'!AN16,Leyenda!$B$30:$E$34,4,FALSE) -> 3 | BP16: =VLOOKUP(AS16,Leyenda!$B$71:$E$75,4,FALSE) -> 10 | BQ16: =+BH16+BI16+BJ16+BK16+BL16+BM16+BN16+BO16+BP16 -> 31 | BR16: =+BC16+BD16+BB16+BE16+BF16 -> 35 | BS16: =1-N16 -> 0.26 | BT16: Clasificaçao SUCS (Mecanica de Solos)
A17: Brejo Seco | B17: 2024 | C17: PNM | D17: GEOTEC-01 | E17: 40 | F17: 40 | G17: P025_Silica_Zone | H17: =+F17 -> 40 | J17: rocha alterada, canga lateritica | K17: =+L16 -> 7 | L17: =+K17+0.5 -> 7.5 | M17: =+L17-K17 -> 0.5 | N17: 0.98 | O17: =1-N17 -> 0.02 | P17: =+M17*N17 -> 0.49 | Q17: =+N17*M17 -> 0.49 | R17: 98 | S17: 5 | T17: =0.11+0.32 -> 0.43 | U17: =0.11+0.1 -> 0.21 | V17: =+U17/M17*100 -> 42 | W17: 5 | Y17: =+W17+X17 -> 5 | Z17: =+IF(T17=0,"",(T17*1000)/Y17) -> 86 | AA17: 50 | AB17: A1 | AC17: F2 | AD17: C4 | AE17: 5 | AF17: 98 | AG17: R2 | AH17: =+AG17 -> R2 | AI17: =+VLOOKUP(AH17,Leyenda!$O$4:$U$10,6,FALSE) -> 0,25-0,35 | AJ17: =+VLOOKUP(AH17,Leyenda!$O$4:$U$10,7,FALSE) -> No Blasting need | AK17: =+VLOOKUP(AJ17,Leyenda!$U$4:$V$10,2,FALSE) -> 2 | AL17: R3 | AM17: =+AH17 -> R2 | AN17: P3 | AO17: W3 | AP17: A4 | AQ17: G3 | AR17: F3 | AS17: Seco | AT17: Solo Limonita%Completamente desconpuesta | AV17: =+VLOOKUP(AN17,Leyenda!$B$30:$E$34,3,FALSE) -> 2 | AW17: =+VLOOKUP('2. Logging Brejo Seco'!AO17,Meteorizacion,3,FALSE) -> 1 | AX17: =+VLOOKUP('2. Logging Brejo Seco'!AP17,Apertura,3,FALSE) -> 0 | AY17: =+VLOOKUP('2. Logging Brejo Seco'!AQ17,Leyenda!$B$55:$D$59,3,FALSE) -> 3 | AZ17: =+VLOOKUP('2. Logging Brejo Seco'!AR17,Relleno,3,FALSE) -> 2 | BA17: =+SUM(AV17:AZ17) -> 8 | BB17: =ROUND(-0.0002*POWER(V17,2)+0.2197*V17,0) -> 9 | BC17: =VLOOKUP(AM17,Leyenda!$B$4:$D$10,3,FALSE) -> 2 | BD17: =IF(Z17="",ROUND((IF(Z17<=400,1.5478*POWER(Z17,0.3351),-2*POWER(10,-6)*POWER(Z17,2)+0.0091*Z17+8.1704)),0),ROUND((IF(Z17<=400,1.5478*POWER(Z17,0.3351),-2*POWER(10,-6)*POWER(Z17,2)+0.0091*Z17+8.1704)),0)) -> 7 | BE17: =+BA17 -> 8 | BF17: =VLOOKUP(AS17,Leyenda!$B$70:$D$75,3,FALSE) -> 15 | BG17: =1.5*BA17+(V17*0.5) -> 33 | BH17: =VLOOKUP(AM17,Leyenda!$B$4:$E$10,4,FALSE) -> 2 | BI17: =IF(Z17="",ROUND(IF(Z17<=50,5,IF(Z17>=3000,30,6.038*LN(Z17)-19.63)),0),ROUND(IF(Z17<=50,5,IF(Z17>=3000,30,6.038*LN(Z17)-19.63)),0)) -> 7 | BJ17: =ROUND(-0.0002*POWER(V17,2)+0.2197*V17,0) -> 9 | BK17: =+VLOOKUP('2. Logging Brejo Seco'!AP17,Leyenda!$B$47:$E$51,4,FALSE) -> 0 | BL17: =+VLOOKUP('2. Logging Brejo Seco'!AQ17,Leyenda!$B$55:$E$59,4,FALSE) -> 3 | BM17: =+VLOOKUP('2. Logging Brejo Seco'!AR17,Leyenda!$B$63:$E$67,3,FALSE) -> 2 | BN17: =+VLOOKUP('2. Logging Brejo Seco'!AO17,Leyenda!$B$39:$E$43,4,FALSE) -> 1 | BO17: =+VLOOKUP('2. Logging Brejo Seco'!AN17,Leyenda!$B$30:$E$34,4,FALSE) -> 3 | BP17: =VLOOKUP(AS17,Leyenda!$B$71:$E$75,4,FALSE) -> 10 | BQ17: =+BH17+BI17+BJ17+BK17+BL17+BM17+BN17+BO17+BP17 -> 37 | BR17: =+BC17+BD17+BB17+BE17+BF17 -> 41 | BS17: =1-N17 -> 0.02
A18: Brejo Seco | B18: 2024 | C18: PNM | D18: GEOTEC-01 | E18: 40 | F18: 40 | G18: P025_Silica_Zone | H18: =+F18 -> 40 | J18: rocha alterada, canga lateritica | K18: =+L17 -> 7.5 | L18: =+K18+0.5 -> 8 | M18: =+L18-K18 -> 0.5 | N18: 1 | O18: =1-N18 -> 0 | P18: =+M18*N18 -> 0.5 | Q18: =+N18*M18 -> 0.5 | R18: 50 | S18: 10 | T18: 0.45 | U18: 0.28 | V18: =+U18/M18*100 -> 56 | W18: 4 | Y18: =+W18+X18 -> 4 | Z18: =+IF(T18=0,"",(T18*1000)/Y18) -> 112.5 | AA18: 68 | AB18: A1 | AC18: F3 | AD18: C4 | AE18: 10 | AF18: 50 | AG18: R3 | AH18: =+AG18 -> R3 | AI18: =+VLOOKUP(AH18,Leyenda!$O$4:$U$10,6,FALSE) -> 0,35-0,50 | AJ18: =+VLOOKUP(AH18,Leyenda!$O$4:$U$10,7,FALSE) -> Easy to blast | AK18: =+VLOOKUP(AJ18,Leyenda!$U$4:$V$10,2,FALSE) -> 3 | AL18: R3 | AM18: =+AH18 -> R3 | AN18: P3 | AO18: W2 | AP18: A3 | AQ18: G3 | AR18: F2 | AS18: Seco | AT18: Muestra de laboratorio GEOMINAS | AV18: =+VLOOKUP(AN18,Leyenda!$B$30:$E$34,3,FALSE) -> 2 | AW18: =+VLOOKUP('2. Logging Brejo Seco'!AO18,Meteorizacion,3,FALSE) -> 3 | AX18: =+VLOOKUP('2. Logging Brejo Seco'!AP18,Apertura,3,FALSE) -> 1 | AY18: =+VLOOKUP('2. Logging Brejo Seco'!AQ18,Leyenda!$B$55:$D$59,3,FALSE) -> 3 | AZ18: =+VLOOKUP('2. Logging Brejo Seco'!AR18,Relleno,3,FALSE) -> 2 | BA18: =+SUM(AV18:AZ18) -> 11 | BB18: =ROUND(-0.0002*POWER(V18,2)+0.2197*V18,0) -> 12 | BC18: =VLOOKUP(AM18,Leyenda!$B$4:$D$10,3,FALSE) -> 4 | BD18: =IF(Z18="",ROUND((IF(Z18<=400,1.5478*POWER(Z18,0.3351),-2*POWER(10,-6)*POWER(Z18,2)+0.0091*Z18+8.1704)),0),ROUND((IF(Z18<=400,1.5478*POWER(Z18,0.3351),-2*POWER(10,-6)*POWER(Z18,2)+0.0091*Z18+8.1704)),0)) -> 8 | BE18: =+BA18 -> 11 | BF18: =VLOOKUP(AS18,Leyenda!$B$70:$D$75,3,FALSE) -> 15 | BG18: =1.5*BA18+(V18*0.5) -> 44.5 | BH18: =VLOOKUP(AM18,Leyenda!$B$4:$E$10,4,FALSE) -> 4 | BI18: =IF(Z18="",ROUND(IF(Z18<=50,5,IF(Z18>=3000,30,6.038*LN(Z18)-19.63)),0),ROUND(IF(Z18<=50,5,IF(Z18>=3000,30,6.038*LN(Z18)-19.63)),0)) -> 9 | BJ18: =ROUND(-0.0002*POWER(V18,2)+0.2197*V18,0) -> 12 | BK18: =+VLOOKUP('2. Logging Brejo Seco'!AP18,Leyenda!$B$47:$E$51,4,FALSE) -> 1 | BL18: =+VLOOKUP('2. Logging Brejo Seco'!AQ18,Leyenda!$B$55:$E$59,4,FALSE) -> 3 | BM18: =+VLOOKUP('2. Logging Brejo Seco'!AR18,Leyenda!$B$63:$E$67,3,FALSE) -> 2 | BN18: =+VLOOKUP('2. Logging Brejo Seco'!AO18,Leyenda!$B$39:$E$43,4,FALSE) -> 3 | BO18: =+VLOOKUP('2. Logging Brejo Seco'!AN18,Leyenda!$B$30:$E$34,4,FALSE) -> 3 | BP18: =VLOOKUP(AS18,Leyenda!$B$71:$E$75,4,FALSE) -> 10 | BQ18: =+BH18+BI18+BJ18+BK18+BL18+BM18+BN18+BO18+BP18 -> 47 | BR18: =+BC18+BD18+BB18+BE18+BF18 -> 50 | BS18: =1-N18 -> 0
A19: Brejo Seco | B19: 2024 | C19: PNM | D19: GEOTEC-01 | E19: 40 | F19: 40 | G19: P025_Silica_Zone | H19: =+F19 -> 40 | J19: rocha alterada, canga lateritica | K19: =+L18 -> 8 | L19: =+K19+0.5 -> 8.5 | M19: =+L19-K19 -> 0.5 | N19: 1 | O19: =1-N19 -> 0 | P19: =+M19*N19 -> 0.5 | Q19: =+N19*M19 -> 0.5 | R19: 100 | S19: 5 | T19: 0.47 | U19: 0.31 | V19: =+U19/M19*100 -> 62 | W19: 2 | Y19: =+W19+X19 -> 2 | Z19: =+IF(T19=0,"",(T19*1000)/Y19) -> 235 | AA19: 86 | AB19: A1 | AC19: F2 | AD19: C4 | AE19: 5 | AF19: 100 | AG19: R3 | AH19: =+AG19 -> R3 | AI19: =+VLOOKUP(AH19,Leyenda!$O$4:$U$10,6,FALSE) -> 0,35-0,50 | AJ19: =+VLOOKUP(AH19,Leyenda!$O$4:$U$10,7,FALSE) -> Easy to blast | AK19: =+VLOOKUP(AJ19,Leyenda!$U$4:$V$10,2,FALSE) -> 3 | AL19: R3 | AM19: =+AH19 -> R3 | AN19: P3 | AO19: W2 | AP19: A3 | AQ19: G3 | AR19: F2 | AS19: Seco | AT19: Venillas de calcedonia | AV19: =+VLOOKUP(AN19,Leyenda!$B$30:$E$34,3,FALSE) -> 2 | AW19: =+VLOOKUP('2. Logging Brejo Seco'!AO19,Meteorizacion,3,FALSE) -> 3 | AX19: =+VLOOKUP('2. Logging Brejo Seco'!AP19,Apertura,3,FALSE) -> 1 | AY19: =+VLOOKUP('2. Logging Brejo Seco'!AQ19,Leyenda!$B$55:$D$59,3,FALSE) -> 3 | AZ19: =+VLOOKUP('2. Logging Brejo Seco'!AR19,Relleno,3,FALSE) -> 2 | BA19: =+SUM(AV19:AZ19) -> 11 | BB19: =ROUND(-0.0002*POWER(V19,2)+0.2197*V19,0) -> 13 | BC19: =VLOOKUP(AM19,Leyenda!$B$4:$D$10,3,FALSE) -> 4 | BD19: =IF(Z19="",ROUND((IF(Z19<=400,1.5478*POWER(Z19,0.3351),-2*POWER(10,-6)*POWER(Z19,2)+0.0091*Z19+8.1704)),0),ROUND((IF(Z19<=400,1.5478*POWER(Z19,0.3351),-2*POWER(10,-6)*POWER(Z19,2)+0.0091*Z19+8.1704)),0)) -> 10 | BE19: =+BA19 -> 11 | BF19: =VLOOKUP(AS19,Leyenda!$B$70:$D$75,3,FALSE) -> 15 | BG19: =1.5*BA19+(V19*0.5) -> 47.5 | BH19: =VLOOKUP(AM19,Leyenda!$B$4:$E$10,4,FALSE) -> 4 | BI19: =IF(Z19="",ROUND(IF(Z19<=50,5,IF(Z19>=3000,30,6.038*LN(Z19)-19.63)),0),ROUND(IF(Z19<=50,5,IF(Z19>=3000,30,6.038*LN(Z19)-19.63)),0)) -> 13 | BJ19: =ROUND(-0.0002*POWER(V19,2)+0.2197*V19,0) -> 13 | BK19: =+VLOOKUP('2. Logging Brejo Seco'!AP19,Leyenda!$B$47:$E$51,4,FALSE) -> 1 | BL19: =+VLOOKUP('2. Logging Brejo Seco'!AQ19,Leyenda!$B$55:$E$59,4,FALSE) -> 3 | BM19: =+VLOOKUP('2. Logging Brejo Seco'!AR19,Leyenda!$B$63:$E$67,3,FALSE) -> 2 | BN19: =+VLOOKUP('2. Logging Brejo Seco'!AO19,Leyenda!$B$39:$E$43,4,FALSE) -> 3 | BO19: =+VLOOKUP('2. Logging Brejo Seco'!AN19,Leyenda!$B$30:$E$34,4,FALSE) -> 3 | BP19: =VLOOKUP(AS19,Leyenda!$B$71:$E$75,4,FALSE) -> 10 | BQ19: =+BH19+BI19+BJ19+BK19+BL19+BM19+BN19+BO19+BP19 -> 52 | BR19: =+BC19+BD19+BB19+BE19+BF19 -> 53 | BS19: =1-N19 -> 0
A20: Brejo Seco | B20: 2024 | C20: PNM | D20: GEOTEC-01 | E20: 40 | F20: 40 | G20: P025_Silica_Zone | H20: =+F20 -> 40 | J20: rocha alterada, canga lateritica | K20: =+L19 -> 8.5 | L20: =+K20+0.5 -> 9 | M20: =+L20-K20 -> 0.5 | N20: 1 | O20: =1-N20 -> 0 | P20: =+M20*N20 -> 0.5 | Q20: =+N20*M20 -> 0.5 | R20: 500 | S20: 1 | T20: 0.35 | U20: 0.16 | V20: =+U20/M20*100 -> 32 | W20: 5 | Y20: =+W20+X20 -> 5 | Z20: =+IF(T20=0,"",(T20*1000)/Y20) -> 70 | AA20: 34 | AB20: A1 | AC20: F1 | AD20: C4 | AE20: 1 | AF20: 500 | AG20: R2 | AH20: =+AG20 -> R2 | AI20: =+VLOOKUP(AH20,Leyenda!$O$4:$U$10,6,FALSE) -> 0,25-0,35 | AJ20: =+VLOOKUP(AH20,Leyenda!$O$4:$U$10,7,FALSE) -> No Blasting need | AK20: =+VLOOKUP(AJ20,Leyenda!$U$4:$V$10,2,FALSE) -> 2 | AL20: R3 | AM20: =+AH20 -> R2 | AN20: P3 | AO20: W3 | AP20: A4 | AQ20: G4 | AR20: F3 | AS20: Seco | AV20: =+VLOOKUP(AN20,Leyenda!$B$30:$E$34,3,FALSE) -> 2 | AW20: =+VLOOKUP('2. Logging Brejo Seco'!AO20,Meteorizacion,3,FALSE) -> 1 | AX20: =+VLOOKUP('2. Logging Brejo Seco'!AP20,Apertura,3,FALSE) -> 0 | AY20: =+VLOOKUP('2. Logging Brejo Seco'!AQ20,Leyenda!$B$55:$D$59,3,FALSE) -> 1 | AZ20: =+VLOOKUP('2. Logging Brejo Seco'!AR20,Relleno,3,FALSE) -> 2 | BA20: =+SUM(AV20:AZ20) -> 6 | BB20: =ROUND(-0.0002*POWER(V20,2)+0.2197*V20,0) -> 7 | BC20: =VLOOKUP(AM20,Leyenda!$B$4:$D$10,3,FALSE) -> 2 | BD20: =IF(Z20="",ROUND((IF(Z20<=400,1.5478*POWER(Z20,0.3351),-2*POWER(10,-6)*POWER(Z20,2)+0.0091*Z20+8.1704)),0),ROUND((IF(Z20<=400,1.5478*POWER(Z20,0.3351),-2*POWER(10,-6)*POWER(Z20,2)+0.0091*Z20+8.1704)),0)) -> 6 | BE20: =+BA20 -> 6 | BF20: =VLOOKUP(AS20,Leyenda!$B$70:$D$75,3,FALSE) -> 15 | BG20: =1.5*BA20+(V20*0.5) -> 25 | BH20: =VLOOKUP(AM20,Leyenda!$B$4:$E$10,4,FALSE) -> 2 | BI20: =IF(Z20="",ROUND(IF(Z20<=50,5,IF(Z20>=3000,30,6.038*LN(Z20)-19.63)),0),ROUND(IF(Z20<=50,5,IF(Z20>=3000,30,6.038*LN(Z20)-19.63)),0)) -> 6 | BJ20: =ROUND(-0.0002*POWER(V20,2)+0.2197*V20,0) -> 7 | BK20: =+VLOOKUP('2. Logging Brejo Seco'!AP20,Leyenda!$B$47:$E$51,4,FALSE) -> 0 | BL20: =+VLOOKUP('2. Logging Brejo Seco'!AQ20,Leyenda!$B$55:$E$59,4,FALSE) -> 1 | BM20: =+VLOOKUP('2. Logging Brejo Seco'!AR20,Leyenda!$B$63:$E$67,3,FALSE) -> 2 | BN20: =+VLOOKUP('2. Logging Brejo Seco'!AO20,Leyenda!$B$39:$E$43,4,FALSE) -> 1 | BO20: =+VLOOKUP('2. Logging Brejo Seco'!AN20,Leyenda!$B$30:$E$34,4,FALSE) -> 3 | BP20: =VLOOKUP(AS20,Leyenda!$B$71:$E$75,4,FALSE) -> 10 | BQ20: =+BH20+BI20+BJ20+BK20+BL20+BM20+BN20+BO20+BP20 -> 32 | BR20: =+BC20+BD20+BB20+BE20+BF20 -> 36 | BS20: =1-N20 -> 0
A21: Brejo Seco | B21: 2024 | C21: PNM | D21: GEOTEC-01 | E21: 40 | F21: 40 | G21: P025_Silica_Zone | H21: =+F21 -> 40 | J21: rocha alterada, canga lateritica | K21: =+L20 -> 9 | L21: =+K21+0.5 -> 9.5 | M21: =+L21-K21 -> 0.5 | N21: 0.8 | O21: =1-N21 -> 0.2 | P21: =+M21*N21 -> 0.4 | Q21: =+N21*M21 -> 0.4 | R21: 400 | S21: 1 | T21: 0.41 | U21: 0.21 | V21: =+U21/M21*100 -> 42 | W21: 4 | Y21: =+W21+X21 -> 4 | Z21: =+IF(T21=0,"",(T21*1000)/Y21) -> 102.5 | AA21: 46 | AB21: A1 | AC21: F1 | AD21: C4 | AE21: 1 | AF21: 400 | AG21: R3 | AH21: =+AG21 -> R3 | AI21: =+VLOOKUP(AH21,Leyenda!$O$4:$U$10,6,FALSE) -> 0,35-0,50 | AJ21: =+VLOOKUP(AH21,Leyenda!$O$4:$U$10,7,FALSE) -> Easy to blast | AK21: =+VLOOKUP(AJ21,Leyenda!$U$4:$V$10,2,FALSE) -> 3 | AL21: R3 | AM21: =+AH21 -> R3 | AN21: P2 | AO21: W2 | AP21: A3 | AQ21: G4 | AR21: F3 | AS21: Seco | AV21: =+VLOOKUP(AN21,Leyenda!$B$30:$E$34,3,FALSE) -> 4 | AW21: =+VLOOKUP('2. Logging Brejo Seco'!AO21,Meteorizacion,3,FALSE) -> 3 | AX21: =+VLOOKUP('2. Logging Brejo Seco'!AP21,Apertura,3,FALSE) -> 1 | AY21: =+VLOOKUP('2. Logging Brejo Seco'!AQ21,Leyenda!$B$55:$D$59,3,FALSE) -> 1 | AZ21: =+VLOOKUP('2. Logging Brejo Seco'!AR21,Relleno,3,FALSE) -> 2 | BA21: =+SUM(AV21:AZ21) -> 11 | BB21: =ROUND(-0.0002*POWER(V21,2)+0.2197*V21,0) -> 9 | BC21: =VLOOKUP(AM21,Leyenda!$B$4:$D$10,3,FALSE) -> 4 | BD21: =IF(Z21="",ROUND((IF(Z21<=400,1.5478*POWER(Z21,0.3351),-2*POWER(10,-6)*POWER(Z21,2)+0.0091*Z21+8.1704)),0),ROUND((IF(Z21<=400,1.5478*POWER(Z21,0.3351),-2*POWER(10,-6)*POWER(Z21,2)+0.0091*Z21+8.1704)),0)) -> 7 | BE21: =+BA21 -> 11 | BF21: =VLOOKUP(AS21,Leyenda!$B$70:$D$75,3,FALSE) -> 15 | BG21: =1.5*BA21+(V21*0.5) -> 37.5 | BH21: =VLOOKUP(AM21,Leyenda!$B$4:$E$10,4,FALSE) -> 4 | BI21: =IF(Z21="",ROUND(IF(Z21<=50,5,IF(Z21>=3000,30,6.038*LN(Z21)-19.63)),0),ROUND(IF(Z21<=50,5,IF(Z21>=3000,30,6.038*LN(Z21)-19.63)),0)) -> 8 | BJ21: =ROUND(-0.0002*POWER(V21,2)+0.2197*V21,0) -> 9 | BK21: =+VLOOKUP('2. Logging Brejo Seco'!AP21,Leyenda!$B$47:$E$51,4,FALSE) -> 1 | BL21: =+VLOOKUP('2. Logging Brejo Seco'!AQ21,Leyenda!$B$55:$E$59,4,FALSE) -> 1 | BM21: =+VLOOKUP('2. Logging Brejo Seco'!AR21,Leyenda!$B$63:$E$67,3,FALSE) -> 2 | BN21: =+VLOOKUP('2. Logging Brejo Seco'!AO21,Leyenda!$B$39:$E$43,4,FALSE) -> 3 | BO21: =+VLOOKUP('2. Logging Brejo Seco'!AN21,Leyenda!$B$30:$E$34,4,FALSE) -> 4 | BP21: =VLOOKUP(AS21,Leyenda!$B$71:$E$75,4,FALSE) -> 10 | BQ21: =+BH21+BI21+BJ21+BK21+BL21+BM21+BN21+BO21+BP21 -> 42 | BR21: =+BC21+BD21+BB21+BE21+BF21 -> 46 | BS21: =1-N21 -> 0.2
A22: Brejo Seco | B22: 2024 | C22: PNM | D22: GEOTEC-01 | E22: 40 | F22: 40 | G22: P025_Silica_Zone | H22: =+F22 -> 40 | J22: Rocha sá, serpentinito alterado | K22: =+L21 -> 9.5 | L22: =+K22+0.5 -> 10 | M22: =+L22-K22 -> 0.5 | N22: 0.86 | O22: =1-N22 -> 0.14 | P22: =+M22*N22 -> 0.43 | Q22: =+N22*M22 -> 0.43 | R22: 86 | S22: 5 | T22: 0.43 | U22: 0.25 | V22: =+U22/M22*100 -> 50 | W22: 4 | Y22: =+W22+X22 -> 4 | Z22: =+IF(T22=0,"",(T22*1000)/Y22) -> 107.5 | AA22: 42 | AB22: A1 | AC22: F2 | AD22: C2 | AE22: 5 | AF22: 86 | AG22: R3 | AH22: =+AG22 -> R3 | AI22: =+VLOOKUP(AH22,Leyenda!$O$4:$U$10,6,FALSE) -> 0,35-0,50 | AJ22: =+VLOOKUP(AH22,Leyenda!$O$4:$U$10,7,FALSE) -> Easy to blast | AK22: =+VLOOKUP(AJ22,Leyenda!$U$4:$V$10,2,FALSE) -> 3 | AL22: R3 | AM22: =+AH22 -> R3 | AN22: P2 | AO22: W1 | AP22: A2 | AQ22: G3 | AR22: F2 | AS22: Seco | AT22: Venillas de calcedonia | AV22: =+VLOOKUP(AN22,Leyenda!$B$30:$E$34,3,FALSE) -> 4 | AW22: =+VLOOKUP('2. Logging Brejo Seco'!AO22,Meteorizacion,3,FALSE) -> 5 | AX22: =+VLOOKUP('2. Logging Brejo Seco'!AP22,Apertura,3,FALSE) -> 3 | AY22: =+VLOOKUP('2. Logging Brejo Seco'!AQ22,Leyenda!$B$55:$D$59,3,FALSE) -> 3 | AZ22: =+VLOOKUP('2. Logging Brejo Seco'!AR22,Relleno,3,FALSE) -> 2 | BA22: =+SUM(AV22:AZ22) -> 17 | BB22: =ROUND(-0.0002*POWER(V22,2)+0.2197*V22,0) -> 10 | BC22: =VLOOKUP(AM22,Leyenda!$B$4:$D$10,3,FALSE) -> 4 | BD22: =IF(Z22="",ROUND((IF(Z22<=400,1.5478*POWER(Z22,0.3351),-2*POWER(10,-6)*POWER(Z22,2)+0.0091*Z22+8.1704)),0),ROUND((IF(Z22<=400,1.5478*POWER(Z22,0.3351),-2*POWER(10,-6)*POWER(Z22,2)+0.0091*Z22+8.1704)),0)) -> 7 | BE22: =+BA22 -> 17 | BF22: =VLOOKUP(AS22,Leyenda!$B$70:$D$75,3,FALSE) -> 15 | BG22: =1.5*BA22+(V22*0.5) -> 50.5 | BH22: =VLOOKUP(AM22,Leyenda!$B$4:$E$10,4,FALSE) -> 4 | BI22: =IF(Z22="",ROUND(IF(Z22<=50,5,IF(Z22>=3000,30,6.038*LN(Z22)-19.63)),0),ROUND(IF(Z22<=50,5,IF(Z22>=3000,30,6.038*LN(Z22)-19.63)),0)) -> 9 | BJ22: =ROUND(-0.0002*POWER(V22,2)+0.2197*V22,0) -> 10 | BK22: =+VLOOKUP('2. Logging Brejo Seco'!AP22,Leyenda!$B$47:$E$51,4,FALSE) -> 3 | BL22: =+VLOOKUP('2. Logging Brejo Seco'!AQ22,Leyenda!$B$55:$E$59,4,FALSE) -> 3 | BM22: =+VLOOKUP('2. Logging Brejo Seco'!AR22,Leyenda!$B$63:$E$67,3,FALSE) -> 2 | BN22: =+VLOOKUP('2. Logging Brejo Seco'!AO22,Leyenda!$B$39:$E$43,4,FALSE) -> 4 | BO22: =+VLOOKUP('2. Logging Brejo Seco'!AN22,Leyenda!$B$30:$E$34,4,FALSE) -> 4 | BP22: =VLOOKUP(AS22,Leyenda!$B$71:$E$75,4,FALSE) -> 10 | BQ22: =+BH22+BI22+BJ22+BK22+BL22+BM22+BN22+BO22+BP22 -> 49 | BR22: =+BC22+BD22+BB22+BE22+BF22 -> 53 | BS22: =1-N22 -> 0.14
A23: Brejo Seco | B23: 2024 | C23: PNM | D23: GEOTEC-01 | E23: 50 | F23: 50 | G23: P0723_Sap_Fe | H23: =+F23 -> 50 | J23: Rocha sá, serpentinito alterado | K23: =+L22 -> 10 | L23: =+K23+0.5 -> 10.5 | M23: =+L23-K23 -> 0.5 | N23: 0.9 | O23: =1-N23 -> 0.1 | P23: =+M23*N23 -> 0.45 | Q23: =+N23*M23 -> 0.45 | R23: 90 | S23: 5 | T23: 0.29 | U23: 0.11 | V23: =+U23/M23*100 -> 22 | W23: 3 | Y23: =+W23+X23 -> 3 | Z23: =+IF(T23=0,"",(T23*1000)/Y23) -> 96.666667 | AA23: 26 | AB23: A1 | AC23: F2 | AD23: C2 | AE23: 5 | AF23: 90 | AG23: R1 | AH23: =+AG23 -> R1 | AI23: =+VLOOKUP(AH23,Leyenda!$O$4:$U$10,6,FALSE) -> 0,15-0,25 | AJ23: =+VLOOKUP(AH23,Leyenda!$O$4:$U$10,7,FALSE) -> No Blasting need | AK23: =+VLOOKUP(AJ23,Leyenda!$U$4:$V$10,2,FALSE) -> 2 | AL23: R2 | AM23: =+AH23 -> R1 | AN23: P4 | AO23: W3 | AP23: A4 | AQ23: G3 | AR23: F3 | AS23: Seco | AT23: Rocha alteradae metrorizada | AV23: =+VLOOKUP(AN23,Leyenda!$B$30:$E$34,3,FALSE) -> 1 | AW23: =+VLOOKUP('2. Logging Brejo Seco'!AO23,Meteorizacion,3,FALSE) -> 1 | AX23: =+VLOOKUP('2. Logging Brejo Seco'!AP23,Apertura,3,FALSE) -> 0 | AY23: =+VLOOKUP('2. Logging Brejo Seco'!AQ23,Leyenda!$B$55:$D$59,3,FALSE) -> 3 | AZ23: =+VLOOKUP('2. Logging Brejo Seco'!AR23,Relleno,3,FALSE) -> 2 | BA23: =+SUM(AV23:AZ23) -> 7 | BB23: =ROUND(-0.0002*POWER(V23,2)+0.2197*V23,0) -> 5 | BC23: =VLOOKUP(AM23,Leyenda!$B$4:$D$10,3,FALSE) -> 1 | BD23: =IF(Z23="",ROUND((IF(Z23<=400,1.5478*POWER(Z23,0.3351),-2*POWER(10,-6)*POWER(Z23,2)+0.0091*Z23+8.1704)),0),ROUND((IF(Z23<=400,1.5478*POWER(Z23,0.3351),-2*POWER(10,-6)*POWER(Z23,2)+0.0091*Z23+8.1704)),0)) -> 7 | BE23: =+BA23 -> 7 | BF23: =VLOOKUP(AS23,Leyenda!$B$70:$D$75,3,FALSE) -> 15 | BG23: =1.5*BA23+(V23*0.5) -> 21.5 | BH23: =VLOOKUP(AM23,Leyenda!$B$4:$E$10,4,FALSE) -> 1 | BI23: =IF(Z23="",ROUND(IF(Z23<=50,5,IF(Z23>=3000,30,6.038*LN(Z23)-19.63)),0),ROUND(IF(Z23<=50,5,IF(Z23>=3000,30,6.038*LN(Z23)-19.63)),0)) -> 8 | BJ23: =ROUND(-0.0002*POWER(V23,2)+0.2197*V23,0) -> 5 | BK23: =+VLOOKUP('2. Logging Brejo Seco'!AP23,Leyenda!$B$47:$E$51,4,FALSE) -> 0 | BL23: =+VLOOKUP('2. Logging Brejo Seco'!AQ23,Leyenda!$B$55:$E$59,4,FALSE) -> 3 | BM23: =+VLOOKUP('2. Logging Brejo Seco'!AR23,Leyenda!$B$63:$E$67,3,FALSE) -> 2 | BN23: =+VLOOKUP('2. Logging Brejo Seco'!AO23,Leyenda!$B$39:$E$43,4,FALSE) -> 1 | BO23: =+VLOOKUP('2. Logging Brejo Seco'!AN23,Leyenda!$B$30:$E$34,4,FALSE) -> 1 | BP23: =VLOOKUP(AS23,Leyenda!$B$71:$E$75,4,FALSE) -> 10 | BQ23: =+BH23+BI23+BJ23+BK23+BL23+BM23+BN23+BO23+BP23 -> 31 | BR23: =+BC23+BD23+BB23+BE23+BF23 -> 35 | BS23: =1-N23 -> 0.1
A24: Brejo Seco | B24: 2024 | C24: PNM | D24: GEOTEC-01 | E24: 50 | F24: 50 | G24: P0723_Sap_Fe | H24: =+F24 -> 50 | J24: Rocha sá, serpentinito alterado | K24: =+L23 -> 10.5 | L24: =+K24+0.5 -> 11 | M24: =+L24-K24 -> 0.5 | N24: 0.64 | O24: =1-N24 -> 0.36 | P24: =+M24*N24 -> 0.32 | Q24: =+N24*M24 -> 0.32 | R24: 16 | S24: 20 | T24: 0.27 | U24: 0 | V24: =+U24/M24*100 -> 0 | W24: 13 | Y24: =+W24+X24 -> 13 | Z24: =+IF(T24=0,"",(T24*1000)/Y24) -> 20.769231 | AA24: 0 | AB24: A4 | AC24: F5 | AD24: C3 | AE24: 20 | AF24: 16 | AG24: R1 | AH24: =+AG24 -> R1 | AI24: =+VLOOKUP(AH24,Leyenda!$O$4:$U$10,6,FALSE) -> 0,15-0,25 | AJ24: =+VLOOKUP(AH24,Leyenda!$O$4:$U$10,7,FALSE) -> No Blasting need | AK24: =+VLOOKUP(AJ24,Leyenda!$U$4:$V$10,2,FALSE) -> 2 | AL24: R2 | AM24: =+AH24 -> R1 | AN24: P4 | AO24: W3 | AP24: A4 | AQ24: G3 | AR24: F3 | AS24: Seco | AT24: Rocha alteradae metrorizada | AV24: =+VLOOKUP(AN24,Leyenda!$B$30:$E$34,3,FALSE) -> 1 | AW24: =+VLOOKUP('2. Logging Brejo Seco'!AO24,Meteorizacion,3,FALSE) -> 1 | AX24: =+VLOOKUP('2. Logging Brejo Seco'!AP24,Apertura,3,FALSE) -> 0 | AY24: =+VLOOKUP('2. Logging Brejo Seco'!AQ24,Leyenda!$B$55:$D$59,3,FALSE) -> 3 | AZ24: =+VLOOKUP('2. Logging Brejo Seco'!AR24,Relleno,3,FALSE) -> 2 | BA24: =+SUM(AV24:AZ24) -> 7 | BB24: =ROUND(-0.0002*POWER(V24,2)+0.2197*V24,0) -> 0 | BC24: =VLOOKUP(AM24,Leyenda!$B$4:$D$10,3,FALSE) -> 1 | BD24: =IF(Z24="",ROUND((IF(Z24<=400,1.5478*POWER(Z24,0.3351),-2*POWER(10,-6)*POWER(Z24,2)+0.0091*Z24+8.1704)),0),ROUND((IF(Z24<=400,1.5478*POWER(Z24,0.3351),-2*POWER(10,-6)*POWER(Z24,2)+0.0091*Z24+8.1704)),0)) -> 4 | BE24: =+BA24 -> 7 | BF24: =VLOOKUP(AS24,Leyenda!$B$70:$D$75,3,FALSE) -> 15 | BG24: =1.5*BA24+(V24*0.5) -> 10.5 | BH24: =VLOOKUP(AM24,Leyenda!$B$4:$E$10,4,FALSE) -> 1 | BI24: =IF(Z24="",ROUND(IF(Z24<=50,5,IF(Z24>=3000,30,6.038*LN(Z24)-19.63)),0),ROUND(IF(Z24<=50,5,IF(Z24>=3000,30,6.038*LN(Z24)-19.63)),0)) -> 5 | BJ24: =ROUND(-0.0002*POWER(V24,2)+0.2197*V24,0) -> 0 | BK24: =+VLOOKUP('2. Logging Brejo Seco'!AP24,Leyenda!$B$47:$E$51,4,FALSE) -> 0 | BL24: =+VLOOKUP('2. Logging Brejo Seco'!AQ24,Leyenda!$B$55:$E$59,4,FALSE) -> 3 | BM24: =+VLOOKUP('2. Logging Brejo Seco'!AR24,Leyenda!$B$63:$E$67,3,FALSE) -> 2 | BN24: =+VLOOKUP('2. Logging Brejo Seco'!AO24,Leyenda!$B$39:$E$43,4,FALSE) -> 1 | BO24: =+VLOOKUP('2. Logging Brejo Seco'!AN24,Leyenda!$B$30:$E$34,4,FALSE) -> 1 | BP24: =VLOOKUP(AS24,Leyenda!$B$71:$E$75,4,FALSE) -> 10 | BQ24: =+BH24+BI24+BJ24+BK24+BL24+BM24+BN24+BO24+BP24 -> 23 | BR24: =+BC24+BD24+BB24+BE24+BF24 -> 27 | BS24: =1-N24 -> 0.36
